Workbook

Sheet Daily Sales
A2: DAILY SALES - FEBRUARI 2026
A4: Date | B4: Time | D4: Cust | E4: Code | F4: S | G4: P | H4: Item Descriptions | I4: Qty | J4: Price | K4: Discount | L4: Total | M4: Cogs | N4: Margin | O4: Payment | P4: Margin%
A5: 01/02/26 | B5: 10:29:00 | D5: 1 | E5: PK5043 | F5: =A5&E5 -> 01/02/26PK5043 | G5: =O5&A5 -> C01/02/26 | H5: =IFNA(VLOOKUP(TRIM(E5),Master!D:M,4,0),"") -> PUPUK KAMBING 5KG | I5: 1 | J5: =IFNA(VLOOKUP(E5,Master!D:U,14,0),0) -> 15000 | K5: 0 | L5: =J5*I5-K5 -> 15000 | M5: =IFNA(VLOOKUP(TRIM(E5),Master!D:U,13,0),"") -> 8000 | N5: =L5-(M5*I5) -> 7000 | O5: C | P5: =IFERROR((J5-M5)/J5*100,0) -> 46.666667
A6: 01/02/26 | E6: PL3182 | F6: =A6&E6 -> 01/02/26PL3182 | G6: =O6&A6 -> C01/02/26 | H6: =IFNA(VLOOKUP(TRIM(E6),Master!D:M,4,0),"") -> POT MOTIF BUNGA HITAM 25 | I6: 1 | J6: =IFNA(VLOOKUP(E6,Master!D:U,14,0),0) -> 7000 | K6: 0 | L6: =J6*I6-K6 -> 7000 | M6: =IFNA(VLOOKUP(TRIM(E6),Master!D:U,13,0),"") -> 5250 | N6: =L6-(M6*I6) -> 1750 | O6: C | P6: =IFERROR((J6-M6)/J6*100,0) -> 25
A7: 01/02/26 | B7: 11:00:00 | D7: 1 | E7: MT2037 | F7: =A7&E7 -> 01/02/26MT2037 | G7: =O7&A7 -> I01/02/26 | H7: =IFNA(VLOOKUP(TRIM(E7),Master!D:M,4,0),"") -> PUPUK KOMPOS 5KG | I7: 1 | J7: =IFNA(VLOOKUP(E7,Master!D:U,14,0),0) -> 10000 | K7: 0 | L7: =J7*I7-K7 -> 10000 | M7: =IFNA(VLOOKUP(TRIM(E7),Master!D:U,13,0),"") -> 5000 | N7: =L7-(M7*I7) -> 5000 | O7: I | P7: =IFERROR((J7-M7)/J7*100,0) -> 50
A8: 01/02/26 | B8: 11:53:00 | D8: 1 | E8: PL3182 | F8: =A8&E8 -> 01/02/26PL3182 | G8: =O8&A8 -> C01/02/26 | H8: =IFNA(VLOOKUP(TRIM(E8),Master!D:M,4,0),"") -> POT MOTIF BUNGA HITAM 25 | I8: 2 | J8: =IFNA(VLOOKUP(E8,Master!D:U,14,0),0) -> 7000 | K8: 0 | L8: =J8*I8-K8 -> 14000 | M8: =IFNA(VLOOKUP(TRIM(E8),Master!D:U,13,0),"") -> 5250 | N8: =L8-(M8*I8) -> 3500 | O8: C | P8: =IFERROR((J8-M8)/J8*100,0) -> 25
A9: 01/02/26 | B9: 11:53:00 | D9: 1 | E9: PK5041 | F9: =A9&E9 -> 01/02/26PK5041 | G9: =O9&A9 -> C01/02/26 | H9: =IFNA(VLOOKUP(TRIM(E9),Master!D:M,4,0),"") -> PUPUK BOOSTER 76 250ML | I9: 1 | J9: =IFNA(VLOOKUP(E9,Master!D:U,14,0),0) -> 45000 | K9: 0 | L9: =J9*I9-K9 -> 45000 | M9: =IFNA(VLOOKUP(TRIM(E9),Master!D:U,13,0),"") -> 25000 | N9: =L9-(M9*I9) -> 20000 | O9: C | P9: =IFERROR((J9-M9)/J9*100,0) -> 44.444444
A10: 01/02/26 | B10: 12:07:00 | D10: 1 | E10: PK5069 | F10: =A10&E10 -> 01/02/26PK5069 | G10: =O10&A10 -> O01/02/26 | H10: =IFNA(VLOOKUP(TRIM(E10),Master!D:M,4,0),"") -> ROOTUP 100GR | I10: 1 | J10: =IFNA(VLOOKUP(E10,Master!D:U,14,0),0) -> 35000 | K10: 0 | L10: =J10*I10-K10 -> 35000 | M10: =IFNA(VLOOKUP(TRIM(E10),Master!D:U,13,0),"") -> 16200 | N10: =L10-(M10*I10) -> 18800 | O10: O | P10: =IFERROR((J10-M10)/J10*100,0) -> 53.714286
A11: 01/02/26 | E11: PL3028 | F11: =A11&E11 -> 01/02/26PL3028 | G11: =O11&A11 -> O01/02/26 | H11: =IFNA(VLOOKUP(TRIM(E11),Master!D:M,4,0),"") -> KAWAT BONSAI HITAM NO.2 ECERAN | I11: 5 | J11: =IFNA(VLOOKUP(E11,Master!D:U,14,0),0) -> 2000 | K11: 0 | L11: =J11*I11-K11 -> 10000 | M11: =IFNA(VLOOKUP(TRIM(E11),Master!D:U,13,0),"") -> 1220 | N11: =L11-(M11*I11) -> 3900 | O11: O | P11: =IFERROR((J11-M11)/J11*100,0) -> 39
A12: 01/02/26 | E12: PL3115 | F12: =A12&E12 -> 01/02/26PL3115 | G12: =O12&A12 -> O01/02/26 | H12: =IFNA(VLOOKUP(TRIM(E12),Master!D:M,4,0),"") -> POLYBAG 40 | I12: 5 | J12: =IFNA(VLOOKUP(E12,Master!D:U,14,0),0) -> 1000 | K12: 0 | L12: =J12*I12-K12 -> 5000 | M12: =IFNA(VLOOKUP(TRIM(E12),Master!D:U,13,0),"") -> 500 | N12: =L12-(M12*I12) -> 2500 | O12: O | P12: =IFERROR((J12-M12)/J12*100,0) -> 50
A13: 01/02/26 | E13: PL3117 | F13: =A13&E13 -> 01/02/26PL3117 | G13: =O13&A13 -> O01/02/26 | H13: =IFNA(VLOOKUP(TRIM(E13),Master!D:M,4,0),"") -> POLYBAG 50 | I13: 5 | J13: =IFNA(VLOOKUP(E13,Master!D:U,14,0),0) -> 2000 | K13: 0 | L13: =J13*I13-K13 -> 10000 | M13: =IFNA(VLOOKUP(TRIM(E13),Master!D:U,13,0),"") -> 1316 | N13: =L13-(M13*I13) -> 3420 | O13: O | P13: =IFERROR((J13-M13)/J13*100,0) -> 34.2
A14: 01/02/26 | B14: 12:24:00 | D14: 1 | E14: PL3040 | F14: =A14&E14 -> 01/02/26PL3040 | G14: =O14&A14 -> C01/02/26 | H14: =IFNA(VLOOKUP(TRIM(E14),Master!D:M,4,0),"") -> KAWAT BONSAI SILVER NO.1.5 ECERAN | I14: 20 | J14: =IFNA(VLOOKUP(E14,Master!D:U,14,0),0) -> 750 | K14: 0 | L14: =J14*I14-K14 -> 15000 | M14: =IFNA(VLOOKUP(TRIM(E14),Master!D:U,13,0),"") -> 444 | N14: =L14-(M14*I14) -> 6120 | O14: C | P14: =IFERROR((J14-M14)/J14*100,0) -> 40.8
A15: 01/02/26 | B15: 12:24:00 | D15: 1 | E15: MT2053 | F15: =A15&E15 -> 01/02/26MT2053 | G15: =O15&A15 -> C01/02/26 | H15: =IFNA(VLOOKUP(TRIM(E15),Master!D:M,4,0),"") -> TANAH SUBUR 25KG BINTANG TANI | I15: 1 | J15: =IFNA(VLOOKUP(E15,Master!D:U,14,0),0) -> 25000 | K15: 0 | L15: =J15*I15-K15 -> 25000 | M15: =IFNA(VLOOKUP(TRIM(E15),Master!D:U,13,0),"") -> 15000 | N15: =L15-(M15*I15) -> 10000 | O15: C | P15: =IFERROR((J15-M15)/J15*100,0) -> 40
A16: 01/02/26 | E16: PL3113 | F16: =A16&E16 -> 01/02/26PL3113 | G16: =O16&A16 -> C01/02/26 | H16: =IFNA(VLOOKUP(TRIM(E16),Master!D:M,4,0),"") -> POLYBAG 30 | I16: 1 | J16: =IFNA(VLOOKUP(E16,Master!D:U,14,0),0) -> 5000 | K16: 0 | L16: =J16*I16-K16 -> 5000 | M16: =IFNA(VLOOKUP(TRIM(E16),Master!D:U,13,0),"") -> 3500 | N16: =L16-(M16*I16) -> 1500 | O16: C | P16: =IFERROR((J16-M16)/J16*100,0) -> 30
A17: 01/02/26 | B17: 12:48:00 | D17: 1 | E17: MT2050 | F17: =A17&E17 -> 01/02/26MT2050 | G17: =O17&A17 -> C01/02/26 | H17: =IFNA(VLOOKUP(TRIM(E17),Master!D:M,4,0),"") -> TANAH SUBUR 10KG BINTANG TANI | I17: 1 | J17: =IFNA(VLOOKUP(E17,Master!D:U,14,0),0) -> 10000 | K17: 0 | L17: =J17*I17-K17 -> 10000 | M17: =IFNA(VLOOKUP(TRIM(E17),Master!D:U,13,0),"") -> 6000 | N17: =L17-(M17*I17) -> 4000 | O17: C | P17: =IFERROR((J17-M17)/J17*100,0) -> 40
A18: 01/02/26 | B18: 13:32:00 | D18: 1 | E18: MT2053 | F18: =A18&E18 -> 01/02/26MT2053 | G18: =O18&A18 -> C01/02/26 | H18: =IFNA(VLOOKUP(TRIM(E18),Master!D:M,4,0),"") -> TANAH SUBUR 25KG BINTANG TANI | I18: 1 | J18: =IFNA(VLOOKUP(E18,Master!D:U,14,0),0) -> 25000 | K18: 0 | L18: =J18*I18-K18 -> 25000 | M18: =IFNA(VLOOKUP(TRIM(E18),Master!D:U,13,0),"") -> 15000 | N18: =L18-(M18*I18) -> 10000 | O18: C | P18: =IFERROR((J18-M18)/J18*100,0) -> 40
A19: 01/02/26 | E19: PL3066 | F19: =A19&E19 -> 01/02/26PL3066 | G19: =O19&A19 -> C01/02/26 | H19: =IFNA(VLOOKUP(TRIM(E19),Master!D:M,4,0),"") -> BIBIT BINTANG ASIA | I19: 1 | J19: =IFNA(VLOOKUP(E19,Master!D:U,14,0),0) -> 15000 | K19: 0 | L19: =J19*I19-K19 -> 15000 | M19: =IFNA(VLOOKUP(TRIM(E19),Master!D:U,13,0),"") -> 12500 | N19: =L19-(M19*I19) -> 2500 | O19: C | P19: =IFERROR((J19-M19)/J19*100,0) -> 16.666667
A20: 01/02/26 | E20: PL3068 | F20: =A20&E20 -> 01/02/26PL3068 | G20: =O20&A20 -> C01/02/26 | H20: =IFNA(VLOOKUP(TRIM(E20),Master!D:M,4,0),"") -> BIBIT PUTIH | I20: 2 | J20: =IFNA(VLOOKUP(E20,Master!D:U,14,0),0) -> 5000 | K20: 0 | L20: =J20*I20-K20 -> 10000 | M20: =IFNA(VLOOKUP(TRIM(E20),Master!D:U,13,0),"") -> 2000 | N20: =L20-(M20*I20) -> 6000 | O20: C | P20: =IFERROR((J20-M20)/J20*100,0) -> 60
A21: 01/02/26 | B21: 14:15:00 | D21: 1 | E21: PL3042 | F21: =A21&E21 -> 01/02/26PL3042 | G21: =O21&A21 -> O01/02/26 | H21: =IFNA(VLOOKUP(TRIM(E21),Master!D:M,4,0),"") -> KAWAT BONSAI SILVER NO.2 ECERAN | I21: 2 | J21: =IFNA(VLOOKUP(E21,Master!D:U,14,0),0) -> 1500 | K21: 0 | L21: =J21*I21-K21 -> 3000 | M21: =IFNA(VLOOKUP(TRIM(E21),Master!D:U,13,0),"") -> 800 | N21: =L21-(M21*I21) -> 1400 | O21: O | P21: =IFERROR((J21-M21)/J21*100,0) -> 46.666667
A22: 01/02/26 | E22: PL3044 | F22: =A22&E22 -> 01/02/26PL3044 | G22: =O22&A22 -> O01/02/26 | H22: =IFNA(VLOOKUP(TRIM(E22),Master!D:M,4,0),"") -> KAWAT BONSAI SILVER NO.2.5 ECERAN | I22: 4 | J22: =IFNA(VLOOKUP(E22,Master!D:U,14,0),0) -> 2000 | K22: 0 | L22: =J22*I22-K22 -> 8000 | M22: =IFNA(VLOOKUP(TRIM(E22),Master!D:U,13,0),"") -> 1143 | N22: =L22-(M22*I22) -> 3428 | O22: O | P22: =IFERROR((J22-M22)/J22*100,0) -> 42.85
A23: 01/02/26 | B23: 15:49:00 | D23: 1 | E23: MT2008 | F23: =A23&E23 -> 01/02/26MT2008 | G23: =O23&A23 -> C01/02/26 | H23: =IFNA(VLOOKUP(TRIM(E23),Master!D:M,4,0),"") -> COCOPEAT NON FERMENTASI 10KG | I23: 1 | J23: =IFNA(VLOOKUP(E23,Master!D:U,14,0),0) -> 10000 | K23: -5000 | L23: =J23*I23-K23 -> 15000 | M23: =IFNA(VLOOKUP(TRIM(E23),Master!D:U,13,0),"") -> 6000 | N23: =L23-(M23*I23) -> 9000 | O23: C | P23: =IFERROR((J23-M23)/J23*100,0) -> 40
A24: 01/02/26 | B24: 15:49:00 | D24: 1 | E24: MT2008 | F24: =A24&E24 -> 01/02/26MT2008 | G24: =O24&A24 -> C01/02/26 | H24: =IFNA(VLOOKUP(TRIM(E24),Master!D:M,4,0),"") -> COCOPEAT NON FERMENTASI 10KG | I24: 1 | J24: =IFNA(VLOOKUP(E24,Master!D:U,14,0),0) -> 10000 | K24: -5000 | L24: =J24*I24-K24 -> 15000 | M24: =IFNA(VLOOKUP(TRIM(E24),Master!D:U,13,0),"") -> 6000 | N24: =L24-(M24*I24) -> 9000 | O24: C | P24: =IFERROR((J24-M24)/J24*100,0) -> 40
A25: 01/02/26 | E25: MT2044 | F25: =A25&E25 -> 01/02/26MT2044 | G25: =O25&A25 -> C01/02/26 | H25: =IFNA(VLOOKUP(TRIM(E25),Master!D:M,4,0),"") -> SEKAM MENTAH 10KG | I25: 1 | J25: =IFNA(VLOOKUP(E25,Master!D:U,14,0),0) -> 10000 | K25: 0 | L25: =J25*I25-K25 -> 10000 | M25: =IFNA(VLOOKUP(TRIM(E25),Master!D:U,13,0),"") -> 6000 | N25: =L25-(M25*I25) -> 4000 | O25: C | P25: =IFERROR((J25-M25)/J25*100,0) -> 40
A26: 01/02/26 | B26: 16:56:00 | D26: 1 | E26: PL3040 | F26: =A26&E26 -> 01/02/26PL3040 | G26: =O26&A26 -> O01/02/26 | H26: =IFNA(VLOOKUP(TRIM(E26),Master!D:M,4,0),"") -> KAWAT BONSAI SILVER NO.1.5 ECERAN | I26: 12 | J26: =IFNA(VLOOKUP(E26,Master!D:U,14,0),0) -> 750 | K26: 0 | L26: =J26*I26-K26 -> 9000 | M26: =IFNA(VLOOKUP(TRIM(E26),Master!D:U,13,0),"") -> 444 | N26: =L26-(M26*I26) -> 3672 | O26: O | P26: =IFERROR((J26-M26)/J26*100,0) -> 40.8
A27: 01/02/26 | B27: 17:35:00 | D27: 1 | E27: MT2053 | F27: =A27&E27 -> 01/02/26MT2053 | G27: =O27&A27 -> C01/02/26 | H27: =IFNA(VLOOKUP(TRIM(E27),Master!D:M,4,0),"") -> TANAH SUBUR 25KG BINTANG TANI | I27: 2 | J27: =IFNA(VLOOKUP(E27,Master!D:U,14,0),0) -> 25000 | K27: 0 | L27: =J27*I27-K27 -> 50000 | M27: =IFNA(VLOOKUP(TRIM(E27),Master!D:U,13,0),"") -> 15000 | N27: =L27-(M27*I27) -> 20000 | O27: C | P27: =IFERROR((J27-M27)/J27*100,0) -> 40
A28: 02/02/26 | B28: 08:34:00 | D28: 1 | E28: PK5011 | F28: =A28&E28 -> 02/02/26PK5011 | G28: =O28&A28 -> O02/02/26 | H28: =IFNA(VLOOKUP(TRIM(E28),Master!D:M,4,0),"") -> DEKASTAR 131313 KTK 500GR | I28: 1 | J28: =IFNA(VLOOKUP(E28,Master!D:U,14,0),0) -> 95000 | K28: 0 | L28: =J28*I28-K28 -> 95000 | M28: =IFNA(VLOOKUP(TRIM(E28),Master!D:U,13,0),"") -> 74000 | N28: =L28-(M28*I28) -> 21000 | O28: O | P28: =IFERROR((J28-M28)/J28*100,0) -> 22.105263
A29: 02/02/26 | B29: 10:00:00 | D29: 1 | E29: PL3089 | F29: =A29&E29 -> 02/02/26PL3089 | G29: =O29&A29 -> I02/02/26 | H29: =IFNA(VLOOKUP(TRIM(E29),Master!D:M,4,0),"") -> SPRAYER 1LITER | I29: 1 | J29: =IFNA(VLOOKUP(E29,Master!D:U,14,0),0) -> 35000 | K29: 0 | L29: =J29*I29-K29 -> 35000 | M29: =IFNA(VLOOKUP(TRIM(E29),Master!D:U,13,0),"") -> 29000 | N29: =L29-(M29*I29) -> 6000 | O29: I | P29: =IFERROR((J29-M29)/J29*100,0) -> 17.142857
A30: 02/02/26 | B30: 10:00:00 | D30: 1 | E30: PL3090 | F30: =A30&E30 -> 02/02/26PL3090 | G30: =O30&A30 -> I02/02/26 | H30: =IFNA(VLOOKUP(TRIM(E30),Master!D:M,4,0),"") -> SPRAYER 2LITER | I30: 1 | J30: =IFNA(VLOOKUP(E30,Master!D:U,14,0),0) -> 43000 | K30: 0 | L30: =J30*I30-K30 -> 43000 | M30: =IFNA(VLOOKUP(TRIM(E30),Master!D:U,13,0),"") -> 33000 | N30: =L30-(M30*I30) -> 10000 | O30: I | P30: =IFERROR((J30-M30)/J30*100,0) -> 23.255814
A31: 02/02/26 | B31: 10:24:00 | D31: 1 | E31: PK5064 | F31: =A31&E31 -> 02/02/26PK5064 | G31: =O31&A31 -> C02/02/26 | H31: =IFNA(VLOOKUP(TRIM(E31),Master!D:M,4,0),"") -> PUPUK UREA 1KG | I31: 1 | J31: =IFNA(VLOOKUP(E31,Master!D:U,14,0),0) -> 14000 | K31: 0 | L31: =J31*I31-K31 -> 14000 | M31: =IFNA(VLOOKUP(TRIM(E31),Master!D:U,13,0),"") -> 10000 | N31: =L31-(M31*I31) -> 4000 | O31: C | P31: =IFERROR((J31-M31)/J31*100,0) -> 28.571429
A32: 02/02/26 | B32: 12:54:00 | D32: 1 | E32: PL3042 | F32: =A32&E32 -> 02/02/26PL3042 | G32: =O32&A32 -> O02/02/26 | H32: =IFNA(VLOOKUP(TRIM(E32),Master!D:M,4,0),"") -> KAWAT BONSAI SILVER NO.2 ECERAN | I32: 5 | J32: =IFNA(VLOOKUP(E32,Master!D:U,14,0),0) -> 1500 | K32: 0 | L32: =J32*I32-K32 -> 7500 | M32: =IFNA(VLOOKUP(TRIM(E32),Master!D:U,13,0),"") -> 800 | N32: =L32-(M32*I32) -> 3500 | O32: O | P32: =IFERROR((J32-M32)/J32*100,0) -> 46.666667
A33: 02/02/26 | E33: MT2041 | F33: =A33&E33 -> 02/02/26MT2041 | G33: =O33&A33 -> O02/02/26 | H33: =IFNA(VLOOKUP(TRIM(E33),Master!D:M,4,0),"") -> SEKAM BAKAR 5KG | I33: 1 | J33: =IFNA(VLOOKUP(E33,Master!D:U,14,0),0) -> 8000 | K33: 0 | L33: =J33*I33-K33 -> 8000 | M33: =IFNA(VLOOKUP(TRIM(E33),Master!D:U,13,0),"") -> 3400 | N33: =L33-(M33*I33) -> 4600 | O33: O | P33: =IFERROR((J33-M33)/J33*100,0) -> 57.5
A34: 02/02/26 | E34: PK5068 | F34: =A34&E34 -> 02/02/26PK5068 | G34: =O34&A34 -> O02/02/26 | H34: =IFNA(VLOOKUP(TRIM(E34),Master!D:M,4,0),"") -> PUPUK ZA 1KG | I34: 1 | J34: =IFNA(VLOOKUP(E34,Master!D:U,14,0),0) -> 9000 | K34: 0 | L34: =J34*I34-K34 -> 9000 | M34: =IFNA(VLOOKUP(TRIM(E34),Master!D:U,13,0),"") -> 6000 | N34: =L34-(M34*I34) -> 3000 | O34: O | P34: =IFERROR((J34-M34)/J34*100,0) -> 33.333333
A35: 02/02/26 | E35: PK5066 | F35: =A35&E35 -> 02/02/26PK5066 | G35: =O35&A35 -> O02/02/26 | H35: =IFNA(VLOOKUP(TRIM(E35),Master!D:M,4,0),"") -> PUPUK XPK 1KG | I35: 1 | J35: =IFNA(VLOOKUP(E35,Master!D:U,14,0),0) -> 90000 | K35: 0 | L35: =J35*I35-K35 -> 90000 | M35: =IFNA(VLOOKUP(TRIM(E35),Master!D:U,13,0),"") -> 75000 | N35: =L35-(M35*I35) -> 15000 | O35: O | P35: =IFERROR((J35-M35)/J35*100,0) -> 16.666667
A36: 02/02/26 | B36: 16:08:00 | D36: 1 | E36: MT2050 | F36: =A36&E36 -> 02/02/26MT2050 | G36: =O36&A36 -> C02/02/26 | H36: =IFNA(VLOOKUP(TRIM(E36),Master!D:M,4,0),"") -> TANAH SUBUR 10KG BINTANG TANI | I36: 1 | J36: =IFNA(VLOOKUP(E36,Master!D:U,14,0),0) -> 10000 | K36: 0 | L36: =J36*I36-K36 -> 10000 | M36: =IFNA(VLOOKUP(TRIM(E36),Master!D:U,13,0),"") -> 6000 | N36: =L36-(M36*I36) -> 4000 | O36: C | P36: =IFERROR((J36-M36)/J36*100,0) -> 40
A37: 02/02/26 | E37: MT2044 | F37: =A37&E37 -> 02/02/26MT2044 | G37: =O37&A37 -> C02/02/26 | H37: =IFNA(VLOOKUP(TRIM(E37),Master!D:M,4,0),"") -> SEKAM MENTAH 10KG | I37: 1 | J37: =IFNA(VLOOKUP(E37,Master!D:U,14,0),0) -> 10000 | K37: 0 | L37: =J37*I37-K37 -> 10000 | M37: =IFNA(VLOOKUP(TRIM(E37),Master!D:U,13,0),"") -> 6000 | N37: =L37-(M37*I37) -> 4000 | O37: C | P37: =IFERROR((J37-M37)/J37*100,0) -> 40
A38: 02/02/26 | E38: PK5043 | F38: =A38&E38 -> 02/02/26PK5043 | G38: =O38&A38 -> C02/02/26 | H38: =IFNA(VLOOKUP(TRIM(E38),Master!D:M,4,0),"") -> PUPUK KAMBING 5KG | I38: 1 | J38: =IFNA(VLOOKUP(E38,Master!D:U,14,0),0) -> 15000 | K38: 0 | L38: =J38*I38-K38 -> 15000 | M38: =IFNA(VLOOKUP(TRIM(E38),Master!D:U,13,0),"") -> 8000 | N38: =L38-(M38*I38) -> 7000 | O38: C | P38: =IFERROR((J38-M38)/J38*100,0) -> 46.666667
A39: 02/02/26 | B39: 17:22:00 | D39: 1 | E39: PL3040 | F39: =A39&E39 -> 02/02/26PL3040 | G39: =O39&A39 -> O02/02/26 | H39: =IFNA(VLOOKUP(TRIM(E39),Master!D:M,4,0),"") -> KAWAT BONSAI SILVER NO.1.5 ECERAN | I39: 5 | J39: =IFNA(VLOOKUP(E39,Master!D:U,14,0),0) -> 750 | K39: 0 | L39: =J39*I39-K39 -> 3750 | M39: =IFNA(VLOOKUP(TRIM(E39),Master!D:U,13,0),"") -> 444 | N39: =L39-(M39*I39) -> 1530 | O39: O | P39: =IFERROR((J39-M39)/J39*100,0) -> 40.8
A40: 02/02/26 | B40: 18:40:00 | D40: 1 | E40: MT2050 | F40: =A40&E40 -> 02/02/26MT2050 | G40: =O40&A40 -> C02/02/26 | H40: =IFNA(VLOOKUP(TRIM(E40),Master!D:M,4,0),"") -> TANAH SUBUR 10KG BINTANG TANI | I40: 1 | J40: =IFNA(VLOOKUP(E40,Master!D:U,14,0),0) -> 10000 | K40: 0 | L40: =J40*I40-K40 -> 10000 | M40: =IFNA(VLOOKUP(TRIM(E40),Master!D:U,13,0),"") -> 6000 | N40: =L40-(M40*I40) -> 4000 | O40: C | P40: =IFERROR((J40-M40)/J40*100,0) -> 40
A41: 02/02/26 | B41: 18:40:00 | D41: 1 | E41: MT2053 | F41: =A41&E41 -> 02/02/26MT2053 | G41: =O41&A41 -> C02/02/26 | H41: =IFNA(VLOOKUP(TRIM(E41),Master!D:M,4,0),"") -> TANAH SUBUR 25KG BINTANG TANI | I41: 2 | J41: =IFNA(VLOOKUP(E41,Master!D:U,14,0),0) -> 25000 | K41: 0 | L41: =J41*I41-K41 -> 50000 | M41: =IFNA(VLOOKUP(TRIM(E41),Master!D:U,13,0),"") -> 15000 | N41: =L41-(M41*I41) -> 20000 | O41: C | P41: =IFERROR((J41-M41)/J41*100,0) -> 40
A42: 03/02/26 | B42: 10:38:00 | D42: 1 | E42: PL3040 | F42: =A42&E42 -> 03/02/26PL3040 | G42: =O42&A42 -> O03/02/26 | H42: =IFNA(VLOOKUP(TRIM(E42),Master!D:M,4,0),"") -> KAWAT BONSAI SILVER NO.1.5 ECERAN | I42: 12 | J42: =IFNA(VLOOKUP(E42,Master!D:U,14,0),0) -> 750 | K42: 0 | L42: =J42*I42-K42 -> 9000 | M42: =IFNA(VLOOKUP(TRIM(E42),Master!D:U,13,0),"") -> 444 | N42: =L42-(M42*I42) -> 3672 | O42: O | P42: =IFERROR((J42-M42)/J42*100,0) -> 40.8
...

Sheet Master
D3: 1 | E3: 2 | F3: 3 | G3: 4 | H3: 5 | I3: 6 | J3: 7 | K3: 8 | L3: 9 | M3: 10 | N3: 11 | O3: 12 | P3: 13 | Q3: 14 | R3: 15 | S3: 16 | T3: 17 | U3: 18 | V3: 19 | W3: 20 | X3: 21 | Y3: 22
A4: CODE | B4: COUNTER | D4: BARCODE | E4: CATEGORY | F4: SUB CATEGORY | G4: ITEM DESCRIPTIONS | H4: NOTES | I4: COGS | J4: SELL PRICE | K4: MARGIN | L4: MARGIN VAL | M4: VENDOR | N4: 01/12/24 | O4: HJ | P4: 02/12/24 | Q4: HJ | R4: 03/11/24 | S4: HJ | T4: 04/11/24 | U4: HJ | V4: 05/11/24 | W4: HJ | X4: 06/11/24 | Y4: HJ
A5: OK | B5: =IF(A4=A5,B4+1,1) -> 1 | C5: =IF(A4=A5,C4,C4+1) -> 1 | D5: OK1001 | E5: LAIN LAIN | F5: LAIN LAIN | G5: ETHREL 100ML | J5: 65000 | K5: =(J5-I5)/J5*100 -> 100 | L5: =J5-I5 -> 65000 | M5: SHOPEE | N5: =I5 | O5: =J5 -> 65000 | P5: =N5 | Q5: =O5 -> 65000
A6: OK | B6: =IF(A5=A6,B5+1,1) -> 2 | C6: =IF(A5=A6,C5,C5+1) -> 1 | D6: OK1002 | E6: LAIN LAIN | F6: LAIN LAIN | G6: KARANG | I6: 1 | J6: 1 | K6: =(J6-I6)/J6*100 -> 0 | L6: =J6-I6 -> 0 | N6: 1 | O6: 1 | P6: =N6 -> 1 | Q6: =O6 -> 1
A7: OK | B7: =IF(A6=A7,B6+1,1) -> 3 | C7: =IF(A6=A7,C6,C6+1) -> 1 | D7: OK1003 | E7: LAIN LAIN | F7: LAIN LAIN | G7: ONGKIR | I7: 0 | J7: 1 | K7: =(J7-I7)/J7*100 -> 100 | L7: =J7-I7 -> 1 | N7: 0 | O7: 1 | P7: =N7 -> 0 | Q7: =O7 -> 1
A8: MT | B8: =IF(A7=A8,B7+1,1) -> 1 | C8: =IF(A7=A8,C7,C7+1) -> 2 | D8: MT2001 | E8: MEDIA TANAM | F8: MEDIA TANAM | G8: ANDAM | I8: 7142.8571 | J8: 15000 | K8: =(J8-I8)/J8*100 -> 52.380952 | L8: =J8-I8 -> 7857.1429 | N8: 7142.8571 | O8: 15000 | P8: =N8 -> 7142.8571 | Q8: =O8 -> 15000
A9: MT | B9: =IF(A8=A9,B8+1,1) -> 2 | C9: =IF(A8=A9,C8,C8+1) -> 2 | D9: MT2002 | E9: MEDIA TANAM | F9: MEDIA TANAM | G9: ANDAM 25KG | I9: 30000 | J9: 50000 | K9: =(J9-I9)/J9*100 -> 40 | L9: =J9-I9 -> 20000 | N9: =I9 -> 30000 | O9: =J9 -> 50000 | P9: =N9 -> 30000 | Q9: =O9 -> 50000
A10: MT | B10: =IF(A9=A10,B9+1,1) -> 3 | C10: =IF(A9=A10,C9,C9+1) -> 2 | D10: MT2003 | E10: MEDIA TANAM | F10: MEDIA TANAM | G10: ARANG 5KG | I10: 8000 | J10: 15000 | K10: =(J10-I10)/J10*100 -> 46.666667 | L10: =J10-I10 -> 7000 | N10: 8000 | O10: 15000 | P10: =N10 -> 8000 | Q10: =O10 -> 15000
A11: MT | B11: =IF(A10=A11,B10+1,1) -> 4 | C11: =IF(A10=A11,C10,C10+1) -> 2 | D11: MT2004 | E11: MEDIA TANAM | F11: MEDIA TANAM | G11: COCO FIBER | I11: 8000 | J11: 13000 | K11: =(J11-I11)/J11*100 -> 38.461538 | L11: =J11-I11 -> 5000 | M11: BINTANG TANI | N11: 8000 | O11: 13000 | P11: =N11 -> 8000 | Q11: =O11 -> 13000
A12: MT | B12: =IF(A11=A12,B11+1,1) -> 5 | C12: =IF(A11=A12,C11,C11+1) -> 2 | D12: MT2005 | E12: MEDIA TANAM | F12: MEDIA TANAM | G12: COCOPEAT BLOCK MINI | I12: 18000 | J12: 25000 | K12: =(J12-I12)/J12*100 -> 28 | L12: =J12-I12 -> 7000 | N12: 18000 | O12: 25000 | P12: =N12 -> 18000 | Q12: =O12 -> 25000
A13: MT | B13: =IF(A12=A13,B12+1,1) -> 6 | C13: =IF(A12=A13,C12,C12+1) -> 2 | D13: MT2006 | E13: MEDIA TANAM | F13: MEDIA TANAM | G13: COCOPEAT FERMENTASI 10KG | I13: 10000 | J13: 15000 | K13: =(J13-I13)/J13*100 -> 33.333333 | L13: =J13-I13 -> 5000 | M13: VENDOR OTHER | N13: 10000 | O13: 15000 | P13: =N13 -> 10000 | Q13: =O13 -> 15000
A14: MT | B14: =IF(A13=A14,B13+1,1) -> 7 | C14: =IF(A13=A14,C13,C13+1) -> 2 | D14: MT2007 | E14: MEDIA TANAM | F14: MEDIA TANAM | G14: COCOPEAT FERMENTASI 5KG | I14: 3000 | J14: 8000 | K14: =(J14-I14)/J14*100 -> 62.5 | L14: =J14-I14 -> 5000 | N14: =I14 -> 3000 | O14: =J14 -> 8000 | P14: =N14 -> 3000 | Q14: =O14 -> 8000
A15: MT | B15: =IF(A14=A15,B14+1,1) -> 8 | C15: =IF(A14=A15,C14,C14+1) -> 2 | D15: MT2008 | E15: MEDIA TANAM | F15: MEDIA TANAM | G15: COCOPEAT NON FERMENTASI 10KG | I15: 6000 | J15: 10000 | K15: =(J15-I15)/J15*100 -> 40 | L15: =J15-I15 -> 4000 | M15: BINTANG TANI | N15: 6000 | O15: 10000 | P15: =N15 -> 6000 | Q15: =O15 -> 10000
A16: MT | B16: =IF(A15=A16,B15+1,1) -> 9 | C16: =IF(A15=A16,C15,C15+1) -> 2 | D16: MT2009 | E16: MEDIA TANAM | F16: MEDIA TANAM | G16: COCOPEAT NON FERMENTASI 5KG | I16: 3000 | J16: 5000 | K16: =(J16-I16)/J16*100 -> 40 | L16: =J16-I16 -> 2000 | N16: 3000 | O16: 5000 | P16: =N16 -> 3000 | Q16: =O16 -> 5000
A17: MT | B17: =IF(A16=A17,B16+1,1) -> 10 | C17: =IF(A16=A17,C16,C16+1) -> 2 | D17: MT2010 | E17: MEDIA TANAM | F17: MEDIA TANAM | G17: DAUN BAMBU | I17: 6000 | J17: 12000 | K17: =(J17-I17)/J17*100 -> 50 | L17: =J17-I17 -> 6000 | M17: BINTANG TANI | N17: 6000 | O17: 12000 | P17: =N17 -> 6000 | Q17: =O17 -> 12000
A18: MT | B18: =IF(A17=A18,B17+1,1) -> 11 | C18: =IF(A17=A18,C17,C17+1) -> 2 | D18: MT2011 | E18: MEDIA TANAM | F18: MEDIA TANAM | G18: HUMUS BAMBU | I18: 4285.7143 | J18: 12000 | K18: =(J18-I18)/J18*100 -> 64.285714 | L18: =J18-I18 -> 7714.2857 | N18: 4285.7143 | O18: 12000 | P18: =N18 -> 4285.7143 | Q18: =O18 -> 12000
A19: MT | B19: =IF(A18=A19,B18+1,1) -> 12 | C19: =IF(A18=A19,C18,C18+1) -> 2 | D19: MT2012 | E19: MEDIA TANAM | F19: MEDIA TANAM | G19: HUMUS BAMBU 25KG | I19: 30000 | J19: 50000 | K19: =(J19-I19)/J19*100 -> 40 | L19: =J19-I19 -> 20000 | M19: GENTA | N19: =I19 -> 30000 | O19: =J19 -> 50000 | P19: =N19 -> 30000 | Q19: =O19 -> 50000
A20: MT | B20: =IF(A19=A20,B19+1,1) -> 13 | C20: =IF(A19=A20,C19,C19+1) -> 2 | D20: MT2013 | E20: MEDIA TANAM | F20: MEDIA TANAM | G20: HYDROTON 1KG | I20: 37000 | J20: 50000 | K20: =(J20-I20)/J20*100 -> 26 | L20: =J20-I20 -> 13000 | N20: =I20 -> 37000 | O20: =J20 -> 50000 | P20: =N20 -> 37000 | Q20: =O20 -> 50000
A21: MT | B21: =IF(A20=A21,B20+1,1) -> 14 | C21: =IF(A20=A21,C20,C20+1) -> 2 | D21: MT2014 | E21: MEDIA TANAM | F21: MEDIA TANAM | G21: HYDROTON 500GR | I21: 18500 | J21: 25000 | K21: =(J21-I21)/J21*100 -> 26 | L21: =J21-I21 -> 6500 | N21: =I21 -> 18500 | O21: =J21 -> 25000 | P21: =N21 -> 18500 | Q21: =O21 -> 25000
A22: MT | B22: =IF(A21=A22,B21+1,1) -> 15 | C22: =IF(A21=A22,C21,C21+1) -> 2 | D22: MT2015 | E22: MEDIA TANAM | F22: MEDIA TANAM | G22: MEDIA AROID MIX | I22: 10000 | J22: 15000 | K22: =(J22-I22)/J22*100 -> 33.333333 | L22: =J22-I22 -> 5000 | N22: 10000 | O22: 15000 | P22: =N22 -> 10000 | Q22: =O22 -> 15000
A23: MT | B23: =IF(A22=A23,B22+1,1) -> 16 | C23: =IF(A22=A23,C22,C22+1) -> 2 | D23: MT2016 | E23: MEDIA TANAM | F23: MEDIA TANAM | G23: MOSS HITAM 1 KAMPIL | I23: 50000 | J23: 70000 | K23: =(J23-I23)/J23*100 -> 28.571429 | L23: =J23-I23 -> 20000 | M23: VENDOR OTHER | N23: 50000 | O23: 70000 | P23: =N23 -> 50000 | Q23: =O23 -> 70000
A24: MT | B24: =IF(A23=A24,B23+1,1) -> 17 | C24: =IF(A23=A24,C23,C23+1) -> 2 | D24: MT2017 | E24: MEDIA TANAM | F24: MEDIA TANAM | G24: MOSS HITAM 10KG | I24: 12000 | J24: 20000 | K24: =(J24-I24)/J24*100 -> 40 | L24: =J24-I24 -> 8000 | N24: =I24 -> 12000 | O24: =J24 -> 20000 | P24: =N24 -> 12000 | Q24: =O24 -> 20000
A25: MT | B25: =IF(A24=A25,B24+1,1) -> 18 | C25: =IF(A24=A25,C24,C24+1) -> 2 | D25: MT2018 | E25: MEDIA TANAM | F25: MEDIA TANAM | G25: MOSS HITAM 5KG | I25: 7500 | J25: 12000 | K25: =(J25-I25)/J25*100 -> 37.5 | L25: =J25-I25 -> 4500 | M25: BINTANG TANI | N25: 7500 | O25: 12000 | P25: =N25 -> 7500 | Q25: =O25 -> 12000
A26: MT | B26: =IF(A25=A26,B25+1,1) -> 19 | C26: =IF(A25=A26,C25,C25+1) -> 2 | D26: MT2019 | E26: MEDIA TANAM | F26: MEDIA TANAM | G26: MOSS SPHAGNUM 200GR | I26: =100000/4 -> 25000 | J26: 35000 | K26: =(J26-I26)/J26*100 -> 28.571429 | L26: =J26-I26 -> 10000 | N26: =I26 -> 25000 | O26: =J26 -> 35000 | P26: =N26 -> 25000 | Q26: =O26 -> 35000
A27: MT | B27: =IF(A26=A27,B26+1,1) -> 20 | C27: =IF(A26=A27,C26,C26+1) -> 2 | D27: MT2020 | E27: MEDIA TANAM | F27: MEDIA TANAM | G27: PAKIS CACAH | I27: 7000 | J27: 12000 | K27: =(J27-I27)/J27*100 -> 41.666667 | L27: =J27-I27 -> 5000 | N27: 7000 | O27: 12000 | P27: =N27 -> 7000 | Q27: =O27 -> 12000
A28: MT | B28: =IF(A27=A28,B27+1,1) -> 21 | C28: =IF(A27=A28,C27,C27+1) -> 2 | D28: MT2021 | E28: MEDIA TANAM | F28: MEDIA TANAM | G28: PAPAN PAKIS | I28: 5000 | J28: 6000 | K28: =(J28-I28)/J28*100 -> 16.666667 | L28: =J28-I28 -> 1000 | N28: 4000 | O28: 6000 | P28: =N28 -> 4000 | Q28: =O28 -> 6000
A29: MT | B29: =IF(A28=A29,B28+1,1) -> 22 | C29: =IF(A28=A29,C28,C28+1) -> 2 | D29: MT2022 | E29: MEDIA TANAM | F29: MEDIA TANAM | G29: PASIR MALANG 10KG | I29: 8000 | J29: 15000 | K29: =(J29-I29)/J29*100 -> 46.666667 | L29: =J29-I29 -> 7000 | M29: BINTANG TANI | N29: 8000 | O29: 15000 | P29: =N29 -> 8000 | Q29: =O29 -> 15000
A30: MT | B30: =IF(A29=A30,B29+1,1) -> 23 | C30: =IF(A29=A30,C29,C29+1) -> 2 | D30: MT2023 | E30: MEDIA TANAM | F30: MEDIA TANAM | G30: PASIR MALANG 1KG | I30: =8500/10 -> 850 | J30: 3000 | K30: =(J30-I30)/J30*100 -> 71.666667 | L30: =J30-I30 -> 2150 | N30: =I30 -> 850 | O30: =J30 -> 3000 | P30: =N30 -> 850 | Q30: =O30 -> 3000
A31: MT | B31: =IF(A30=A31,B30+1,1) -> 24 | C31: =IF(A30=A31,C30,C30+1) -> 2 | D31: MT2024 | E31: MEDIA TANAM | F31: MEDIA TANAM | G31: PASIR MALANG 25KG | I31: 25000 | J31: 35000 | K31: =(J31-I31)/J31*100 -> 28.571429 | L31: =J31-I31 -> 10000 | M31: BINTANG TANI | N31: 25000 | O31: 35000 | P31: =N31 -> 25000 | Q31: =O31 -> 35000
A32: MT | B32: =IF(A31=A32,B31+1,1) -> 25 | C32: =IF(A31=A32,C31,C31+1) -> 2 | D32: MT2025 | E32: MEDIA TANAM | F32: MEDIA TANAM | G32: PASIR MALANG HALUS | I32: 13000 | J32: 17000 | K32: =(J32-I32)/J32*100 -> 23.529412 | L32: =J32-I32 -> 4000 | N32: 13000 | O32: 17000 | P32: =N32 -> 13000 | Q32: =O32 -> 17000
A33: MT | B33: =IF(A32=A33,B32+1,1) -> 26 | C33: =IF(A32=A33,C32,C32+1) -> 2 | D33: MT2026 | E33: MEDIA TANAM | F33: MEDIA TANAM | G33: PASIR MALANG KASAR 10KG | I33: 8000 | J33: 15000 | K33: =(J33-I33)/J33*100 -> 46.666667 | L33: =J33-I33 -> 7000 | M33: BINTANG TANI | N33: 8000 | O33: 15000 | P33: =N33 -> 8000 | Q33: =O33 -> 15000
A34: MT | B34: =IF(A33=A34,B33+1,1) -> 27 | C34: =IF(A33=A34,C33,C33+1) -> 2 | D34: MT2027 | E34: MEDIA TANAM | F34: MEDIA TANAM | G34: PASIR MALANG MERAH KASAR | I34: 15000 | J34: 20000 | K34: =(J34-I34)/J34*100 -> 25 | L34: =J34-I34 -> 5000 | N34: 15000 | O34: 20000 | P34: =N34 -> 15000 | Q34: =O34 -> 20000
A35: MT | B35: =IF(A34=A35,B34+1,1) -> 28 | C35: =IF(A34=A35,C34,C34+1) -> 2 | D35: MT2028 | E35: MEDIA TANAM | F35: MEDIA TANAM | G35: PASIR MALANG MERAH PASIRAN 5KG | I35: 13000 | J35: 17000 | K35: =(J35-I35)/J35*100 -> 23.529412 | L35: =J35-I35 -> 4000 | M35: GENTA | N35: 13000 | O35: 17000 | P35: =N35 -> 13000 | Q35: =O35 -> 17000
A36: MT | B36: =IF(A35=A36,B35+1,1) -> 29 | C36: =IF(A35=A36,C35,C35+1) -> 2 | D36: MT2029 | E36: MEDIA TANAM | F36: MEDIA TANAM | G36: PASIR MALANG MERAH SEDANG 5KG | I36: 13000 | J36: 17000 | K36: =(J36-I36)/J36*100 -> 23.529412 | L36: =J36-I36 -> 4000 | M36: GENTA | N36: 13000 | O36: 17000 | P36: =N36 -> 13000 | Q36: =O36 -> 17000
A37: MT | B37: =IF(A36=A37,B36+1,1) -> 30 | C37: =IF(A36=A37,C36,C36+1) -> 2 | D37: MT2030 | E37: MEDIA TANAM | F37: MEDIA TANAM | G37: PERLITE | I37: 20000 | J37: 40000 | K37: =(J37-I37)/J37*100 -> 50 | L37: =J37-I37 -> 20000 | N37: =I37 -> 20000 | O37: =J37 -> 40000 | P37: =N37 -> 20000 | Q37: =O37 -> 40000
A38: MT | B38: =IF(A37=A38,B37+1,1) -> 31 | C38: =IF(A37=A38,C37,C37+1) -> 2 | D38: MT2031 | E38: MEDIA TANAM | F38: MEDIA TANAM | G38: PINE BARK | I38: 12000 | J38: 20000 | K38: =(J38-I38)/J38*100 -> 40 | L38: =J38-I38 -> 8000 | N38: 12000 | O38: 20000 | P38: =N38 -> 12000 | Q38: =O38 -> 20000
A39: MT | B39: =IF(A38=A39,B38+1,1) -> 32 | C39: =IF(A38=A39,C38,C38+1) -> 2 | D39: MT2032 | E39: MEDIA TANAM | F39: MEDIA TANAM | G39: PUMICE 1-2M PASIRAN /KG | I39: 3250 | J39: 7500 | K39: =(J39-I39)/J39*100 -> 56.666667 | L39: =J39-I39 -> 4250 | M39: GENTA | N39: 3250 | O39: 7500 | P39: =N39 -> 3250 | Q39: =O39 -> 7500
A40: MT | B40: =IF(A39=A40,B39+1,1) -> 33 | C40: =IF(A39=A40,C39,C39+1) -> 2 | D40: MT2033 | E40: MEDIA TANAM | F40: MEDIA TANAM | G40: PUMICE 5-7M SEDANG /KG | I40: 3250 | J40: 7500 | K40: =(J40-I40)/J40*100 -> 56.666667 | L40: =J40-I40 -> 4250 | M40: GENTA | N40: 3250 | O40: 7500 | P40: =N40 -> 3250 | Q40: =O40 -> 7500
A41: MT | B41: =IF(A40=A41,B40+1,1) -> 34 | C41: =IF(A40=A41,C40,C40+1) -> 2 | D41: MT2034 | E41: MEDIA TANAM | F41: MEDIA TANAM | G41: PUMICE/BATU APUNG | J41: 17000 | K41: =(J41-I41)/J41*100 -> 100 | L41: =J41-I41 -> 17000 | O41: 17000 | P41: =N41 | Q41: =O41 -> 17000
A42: MT | B42: =IF(A41=A42,B41+1,1) -> 35 | C42: =IF(A41=A42,C41,C41+1) -> 2 | D42: MT2035 | E42: MEDIA TANAM | F42: MEDIA TANAM | G42: PUPUK KAMBING BUTIRAN | I42: 8000 | J42: 15000 | K42: =(J42-I42)/J42*100 -> 46.666667 | L42: =J42-I42 -> 7000 | N42: 8000 | O42: 15000 | P42: =N42 -> 8000 | Q42: =O42 -> 15000
...

Sheet Sales Summary
A2: SALES SUMMARY PER DAY
A4: Date | B4: Total Sales | C4: Margin | D4: Cash | E4: Transfer | F4: Online | G4: Instant | H4: Customer | I4: MT1029
D5: C | E5: T | F5: O | G5: I
A6: 01/02/26 | B6: =SUMIF('Daily Sales'!A:L,A6,'Daily Sales'!L:L) -> 366000 | C6: =SUMIF('Daily Sales'!A:N,A6,'Daily Sales'!N:N) -> 156490 | D6: =SUMIF('Daily Sales'!G:L,$D$5&A6,'Daily Sales'!L:L) -> 276000 | E6: =SUMIF('Daily Sales'!G:L,$E$5&A6,'Daily Sales'!L:L) -> 0 | F6: =SUMIF('Daily Sales'!G:L,$F$5&A6,'Daily Sales'!L:L) -> 80000 | G6: =SUMIF('Daily Sales'!G:L,$G$5&A6,'Daily Sales'!L:L) -> 10000 | H6: =SUMIF('Daily Sales'!A:D,A6,'Daily Sales'!D:D) -> 14 | I6: =SUMIF('Daily Sales'!F:F,A6&$I$4,'Daily Sales'!I:I) -> 0
A7: 02/02/26 | B7: =SUMIF('Daily Sales'!A:L,A7,'Daily Sales'!L:L) -> 400250 | C7: =SUMIF('Daily Sales'!A:N,A7,'Daily Sales'!N:N) -> 107630 | D7: =SUMIF('Daily Sales'!G:L,$D$5&A7,'Daily Sales'!L:L) -> 109000 | E7: =SUMIF('Daily Sales'!G:L,$E$5&A7,'Daily Sales'!L:L) -> 0 | F7: =SUMIF('Daily Sales'!G:L,$F$5&A7,'Daily Sales'!L:L) -> 213250 | G7: =SUMIF('Daily Sales'!G:L,$G$5&A7,'Daily Sales'!L:L) -> 78000 | H7: =SUMIF('Daily Sales'!A:D,A7,'Daily Sales'!D:D) -> 9 | I7: =SUMIF('Daily Sales'!F:F,A7&$I$4,'Daily Sales'!I:I) -> 0
A8: 03/02/26 | B8: =SUMIF('Daily Sales'!A:L,A8,'Daily Sales'!L:L) -> 370000 | C8: =SUMIF('Daily Sales'!A:N,A8,'Daily Sales'!N:N) -> 161722 | D8: =SUMIF('Daily Sales'!G:L,$D$5&A8,'Daily Sales'!L:L) -> 120000 | E8: =SUMIF('Daily Sales'!G:L,$E$5&A8,'Daily Sales'!L:L) -> 50000 | F8: =SUMIF('Daily Sales'!G:L,$F$5&A8,'Daily Sales'!L:L) -> 128000 | G8: =SUMIF('Daily Sales'!G:L,$G$5&A8,'Daily Sales'!L:L) -> 72000 | H8: =SUMIF('Daily Sales'!A:D,A8,'Daily Sales'!D:D) -> 12 | I8: =SUMIF('Daily Sales'!F:F,A8&$I$4,'Daily Sales'!I:I) -> 0
A9: 04/02/26 | B9: =SUMIF('Daily Sales'!A:L,A9,'Daily Sales'!L:L) -> 478500 | C9: =SUMIF('Daily Sales'!A:N,A9,'Daily Sales'!N:N) -> 169028 | D9: =SUMIF('Daily Sales'!G:L,$D$5&A9,'Daily Sales'!L:L) -> 308000 | E9: =SUMIF('Daily Sales'!G:L,$E$5&A9,'Daily Sales'!L:L) -> 60000 | F9: =SUMIF('Daily Sales'!G:L,$F$5&A9,'Daily Sales'!L:L) -> 75500 | G9: =SUMIF('Daily Sales'!G:L,$G$5&A9,'Daily Sales'!L:L) -> 35000 | H9: =SUMIF('Daily Sales'!A:D,A9,'Daily Sales'!D:D) -> 12 | I9: =SUMIF('Daily Sales'!F:F,A9&$I$4,'Daily Sales'!I:I) -> 0
A10: 05/02/26 | B10: =SUMIF('Daily Sales'!A:L,A10,'Daily Sales'!L:L) -> 388750 | C10: =SUMIF('Daily Sales'!A:N,A10,'Daily Sales'!N:N) -> 139840 | D10: =SUMIF('Daily Sales'!G:L,$D$5&A10,'Daily Sales'!L:L) -> 202000 | E10: =SUMIF('Daily Sales'!G:L,$E$5&A10,'Daily Sales'!L:L) -> 48000 | F10: =SUMIF('Daily Sales'!G:L,$F$5&A10,'Daily Sales'!L:L) -> 138750 | G10: =SUMIF('Daily Sales'!G:L,$G$5&A10,'Daily Sales'!L:L) -> 0 | H10: =SUMIF('Daily Sales'!A:D,A10,'Daily Sales'!D:D) -> 10 | I10: =SUMIF('Daily Sales'!F:F,A10&$I$4,'Daily Sales'!I:I) -> 0
A11: 06/02/26 | B11: =SUMIF('Daily Sales'!A:L,A11,'Daily Sales'!L:L) -> 569750 | C11: =SUMIF('Daily Sales'!A:N,A11,'Daily Sales'!N:N) -> 215172 | D11: =SUMIF('Daily Sales'!G:L,$D$5&A11,'Daily Sales'!L:L) -> 245000 | E11: =SUMIF('Daily Sales'!G:L,$E$5&A11,'Daily Sales'!L:L) -> 35000 | F11: =SUMIF('Daily Sales'!G:L,$F$5&A11,'Daily Sales'!L:L) -> 279750 | G11: =SUMIF('Daily Sales'!G:L,$G$5&A11,'Daily Sales'!L:L) -> 10000 | H11: =SUMIF('Daily Sales'!A:D,A11,'Daily Sales'!D:D) -> 13 | I11: =SUMIF('Daily Sales'!F:F,A11&$I$4,'Daily Sales'!I:I) -> 0
A12: 07/02/26 | B12: =SUMIF('Daily Sales'!A:L,A12,'Daily Sales'!L:L) -> 603250 | C12: =SUMIF('Daily Sales'!A:N,A12,'Daily Sales'!N:N) -> 337430 | D12: =SUMIF('Daily Sales'!G:L,$D$5&A12,'Daily Sales'!L:L) -> 552000 | E12: =SUMIF('Daily Sales'!G:L,$E$5&A12,'Daily Sales'!L:L) -> 13000 | F12: =SUMIF('Daily Sales'!G:L,$F$5&A12,'Daily Sales'!L:L) -> 38250 | G12: =SUMIF('Daily Sales'!G:L,$G$5&A12,'Daily Sales'!L:L) -> 0 | H12: =SUMIF('Daily Sales'!A:D,A12,'Daily Sales'!D:D) -> 13 | I12: =SUMIF('Daily Sales'!F:F,A12&$I$4,'Daily Sales'!I:I) -> 0
A13: 08/02/26 | B13: =SUMIF('Daily Sales'!A:L,A13,'Daily Sales'!L:L) -> 668250 | C13: =SUMIF('Daily Sales'!A:N,A13,'Daily Sales'!N:N) -> 243133 | D13: =SUMIF('Daily Sales'!G:L,$D$5&A13,'Daily Sales'!L:L) -> 420000 | E13: =SUMIF('Daily Sales'!G:L,$E$5&A13,'Daily Sales'!L:L) -> 0 | F13: =SUMIF('Daily Sales'!G:L,$F$5&A13,'Daily Sales'!L:L) -> 33250 | G13: =SUMIF('Daily Sales'!G:L,$G$5&A13,'Daily Sales'!L:L) -> 215000 | H13: =SUMIF('Daily Sales'!A:D,A13,'Daily Sales'!D:D) -> 11 | I13: =SUMIF('Daily Sales'!F:F,A13&$I$4,'Daily Sales'!I:I) -> 0
A14: 09/02/26 | B14: =SUMIF('Daily Sales'!A:L,A14,'Daily Sales'!L:L) -> 551750 | C14: =SUMIF('Daily Sales'!A:N,A14,'Daily Sales'!N:N) -> 174586 | D14: =SUMIF('Daily Sales'!G:L,$D$5&A14,'Daily Sales'!L:L) -> 230000 | E14: =SUMIF('Daily Sales'!G:L,$E$5&A14,'Daily Sales'!L:L) -> 0 | F14: =SUMIF('Daily Sales'!G:L,$F$5&A14,'Daily Sales'!L:L) -> 321750 | G14: =SUMIF('Daily Sales'!G:L,$G$5&A14,'Daily Sales'!L:L) -> 0 | H14: =SUMIF('Daily Sales'!A:D,A14,'Daily Sales'!D:D) -> 9 | I14: =SUMIF('Daily Sales'!F:F,A14&$I$4,'Daily Sales'!I:I) -> 0
A15: 10/02/26 | B15: =SUMIF('Daily Sales'!A:L,A15,'Daily Sales'!L:L) -> 594500 | C15: =SUMIF('Daily Sales'!A:N,A15,'Daily Sales'!N:N) -> 211680 | D15: =SUMIF('Daily Sales'!G:L,$D$5&A15,'Daily Sales'!L:L) -> 386000 | E15: =SUMIF('Daily Sales'!G:L,$E$5&A15,'Daily Sales'!L:L) -> 131000 | F15: =SUMIF('Daily Sales'!G:L,$F$5&A15,'Daily Sales'!L:L) -> 57500 | G15: =SUMIF('Daily Sales'!G:L,$G$5&A15,'Daily Sales'!L:L) -> 20000 | H15: =SUMIF('Daily Sales'!A:D,A15,'Daily Sales'!D:D) -> 12 | I15: =SUMIF('Daily Sales'!F:F,A15&$I$4,'Daily Sales'!I:I) -> 0
A16: 11/02/26 | B16: =SUMIF('Daily Sales'!A:L,A16,'Daily Sales'!L:L) -> 563500 | C16: =SUMIF('Daily Sales'!A:N,A16,'Daily Sales'!N:N) -> 175710 | D16: =SUMIF('Daily Sales'!G:L,$D$5&A16,'Daily Sales'!L:L) -> 324000 | E16: =SUMIF('Daily Sales'!G:L,$E$5&A16,'Daily Sales'!L:L) -> 0 | F16: =SUMIF('Daily Sales'!G:L,$F$5&A16,'Daily Sales'!L:L) -> 191500 | G16: =SUMIF('Daily Sales'!G:L,$G$5&A16,'Daily Sales'!L:L) -> 48000 | H16: =SUMIF('Daily Sales'!A:D,A16,'Daily Sales'!D:D) -> 8 | I16: =SUMIF('Daily Sales'!F:F,A16&$I$4,'Daily Sales'!I:I) -> 0
A17: 12/02/26 | B17: =SUMIF('Daily Sales'!A:L,A17,'Daily Sales'!L:L) -> 768000 | C17: =SUMIF('Daily Sales'!A:N,A17,'Daily Sales'!N:N) -> 210500 | D17: =SUMIF('Daily Sales'!G:L,$D$5&A17,'Daily Sales'!L:L) -> 438000 | E17: =SUMIF('Daily Sales'!G:L,$E$5&A17,'Daily Sales'!L:L) -> 10000 | F17: =SUMIF('Daily Sales'!G:L,$F$5&A17,'Daily Sales'!L:L) -> 320000 | G17: =SUMIF('Daily Sales'!G:L,$G$5&A17,'Daily Sales'!L:L) -> 0 | H17: =SUMIF('Daily Sales'!A:D,A17,'Daily Sales'!D:D) -> 14 | I17: =SUMIF('Daily Sales'!F:F,A17&$I$4,'Daily Sales'!I:I) -> 0
... A36: 31/02/25 | B36: =SUMIF('Daily Sales'!A:L,A36,'Daily Sales'!L:L) -> 0 | C36: =SUMIF('Daily Sales'!A:N,A36,'Daily Sales'!N:N) -> 0 | D36: =SUMIF('Daily Sales'!G:L,$D$5&A36,'Daily Sales'!L:L) -> 0 | E36: =SUMIF('Daily Sales'!G:L,$E$5&A36,'Daily Sales'!L:L) -> 0 | F36: =SUMIF('Daily Sales'!G:L,$F$5&A36,'Daily Sales'!L:L) -> 0 | G36: =SUMIF('Daily Sales'!G:L,$G$5&A36,'Daily Sales'!L:L) -> 0 | H36: =SUMIF('Daily Sales'!A:D,A36,'Daily Sales'!D:D) -> 0 | I36: =SUMIF('Daily Sales'!F:F,A36&$I$4,'Daily Sales'!I:I) -> 0
A38: TOTAL | B38: =SUM(B5:B36) -> 13446500 | C38: =SUM(C5:C36) -> 4719545.4 | D38: =SUM(D5:D36) -> 8534500 | E38: =SUM(E5:E36) -> 821000 | F38: =SUM(F5:F36) -> 3255500 | G38: =SUM(G5:G36) -> 835500 | H38: =SUM(H5:H36) -> 278
A39: AVG | B39: =B38/31 -> 433758.06
B40: =B38/26 -> 517173.08 | C40: =C38/B38*100 -> 35.098691

Sheet Stock
A4: Code | B4: Category | C4: Sub Category | D4: NAME TAG TANAMAN | E4: Beginning | F4: 01/11/24 | G4: 02/11/24
A5: MT1001 | B5: MEDIA TANAM | C5: MEDIA TANAM | D5: =VLOOKUP(A5,Master!D:G,4,0) -> #N/A | E5: 0 | F5: =E5+ SUMIF('InOut Inv'!F:H,$F$4&A5,'InOut Inv'!H:H) - SUMIF('Daily Sales'!F:I,$F$4&A5,'Daily Sales'!I:I) -> 0 | G5: =F5+ SUMIF('InOut Inv'!G:I,$F$4&B5,'InOut Inv'!I:I) - SUMIF('Daily Sales'!G:J,$F$4&B5,'Daily Sales'!J:J) -> 0
A6: MT1002 | B6: MEDIA TANAM | C6: MEDIA TANAM | D6: =VLOOKUP(A6,Master!D:G,4,0) -> #N/A | E6: 5 | F6: =E6+ SUMIF('InOut Inv'!F:H,$F$4&A6,'InOut Inv'!H:H) - SUMIF('Daily Sales'!F:I,$F$4&A6,'Daily Sales'!I:I) -> 5 | G6: =F6+ SUMIF('InOut Inv'!G:I,$F$4&B6,'InOut Inv'!I:I) - SUMIF('Daily Sales'!G:J,$F$4&B6,'Daily Sales'!J:J) -> 5
A7: MT1003 | B7: MEDIA TANAM | C7: MEDIA TANAM | D7: =VLOOKUP(A7,Master!D:G,4,0) -> #N/A | E7: 12 | F7: =E7+ SUMIF('InOut Inv'!F:H,$F$4&A7,'InOut Inv'!H:H) - SUMIF('Daily Sales'!F:I,$F$4&A7,'Daily Sales'!I:I) -> 12 | G7: =F7+ SUMIF('InOut Inv'!G:I,$F$4&B7,'InOut Inv'!I:I) - SUMIF('Daily Sales'!G:J,$F$4&B7,'Daily Sales'!J:J) -> 12
A8: MT1004 | B8: MEDIA TANAM | C8: MEDIA TANAM | D8: =VLOOKUP(A8,Master!D:G,4,0) -> #N/A | E8: 5 | F8: =E8+ SUMIF('InOut Inv'!F:H,$F$4&A8,'InOut Inv'!H:H) - SUMIF('Daily Sales'!F:I,$F$4&A8,'Daily Sales'!I:I) -> 5 | G8: =F8+ SUMIF('InOut Inv'!G:I,$F$4&B8,'InOut Inv'!I:I) - SUMIF('Daily Sales'!G:J,$F$4&B8,'Daily Sales'!J:J) -> 5
A9: MT1005 | B9: MEDIA TANAM | C9: MEDIA TANAM | D9: =VLOOKUP(A9,Master!D:G,4,0) -> #N/A | E9: 0 | F9: =E9+ SUMIF('InOut Inv'!F:H,$F$4&A9,'InOut Inv'!H:H) - SUMIF('Daily Sales'!F:I,$F$4&A9,'Daily Sales'!I:I) -> 0 | G9: =F9+ SUMIF('InOut Inv'!G:I,$F$4&B9,'InOut Inv'!I:I) - SUMIF('Daily Sales'!G:J,$F$4&B9,'Daily Sales'!J:J) -> 0
A10: MT1006 | B10: MEDIA TANAM | C10: MEDIA TANAM | D10: =VLOOKUP(A10,Master!D:G,4,0) -> #N/A | E10: 1 | F10: =E10+ SUMIF('InOut Inv'!F:H,$F$4&A10,'InOut Inv'!H:H) - SUMIF('Daily Sales'!F:I,$F$4&A10,'Daily Sales'!I:I) -> 1 | G10: =F10+ SUMIF('InOut Inv'!G:I,$F$4&B10,'InOut Inv'!I:I) - SUMIF('Daily Sales'!G:J,$F$4&B10,'Daily Sales'!J:J) -> 1
A11: MT1007 | B11: MEDIA TANAM | C11: MEDIA TANAM | D11: =VLOOKUP(A11,Master!D:G,4,0) -> #N/A | E11: 3 | F11: =E11+ SUMIF('InOut Inv'!F:H,$F$4&A11,'InOut Inv'!H:H) - SUMIF('Daily Sales'!F:I,$F$4&A11,'Daily Sales'!I:I) -> 3 | G11: =F11+ SUMIF('InOut Inv'!G:I,$F$4&B11,'InOut Inv'!I:I) - SUMIF('Daily Sales'!G:J,$F$4&B11,'Daily Sales'!J:J) -> 3
A12: MT1008 | B12: MEDIA TANAM | C12: MEDIA TANAM | D12: =VLOOKUP(A12,Master!D:G,4,0) -> #N/A | F12: =E12+ SUMIF('InOut Inv'!F:H,$F$4&A12,'InOut Inv'!H:H) - SUMIF('Daily Sales'!F:I,$F$4&A12,'Daily Sales'!I:I) -> 0 | G12: =F12+ SUMIF('InOut Inv'!G:I,$F$4&B12,'InOut Inv'!I:I) - SUMIF('Daily Sales'!G:J,$F$4&B12,'Daily Sales'!J:J) -> 0
A13: MT1009 | B13: MEDIA TANAM | C13: MEDIA TANAM | D13: =VLOOKUP(A13,Master!D:G,4,0) -> #N/A | F13: =E13+ SUMIF('InOut Inv'!F:H,$F$4&A13,'InOut Inv'!H:H) - SUMIF('Daily Sales'!F:I,$F$4&A13,'Daily Sales'!I:I) -> 0 | G13: =F13+ SUMIF('InOut Inv'!G:I,$F$4&B13,'InOut Inv'!I:I) - SUMIF('Daily Sales'!G:J,$F$4&B13,'Daily Sales'!J:J) -> 0
A14: MT1010 | B14: MEDIA TANAM | C14: MEDIA TANAM | D14: =VLOOKUP(A14,Master!D:G,4,0) -> #N/A | E14: 0 | F14: =E14+ SUMIF('InOut Inv'!F:H,$F$4&A14,'InOut Inv'!H:H) - SUMIF('Daily Sales'!F:I,$F$4&A14,'Daily Sales'!I:I) -> 0 | G14: =F14+ SUMIF('InOut Inv'!G:I,$F$4&B14,'InOut Inv'!I:I) - SUMIF('Daily Sales'!G:J,$F$4&B14,'Daily Sales'!J:J) -> 0
A15: MT1011 | B15: MEDIA TANAM | C15: MEDIA TANAM | D15: =VLOOKUP(A15,Master!D:G,4,0) -> #N/A | E15: 3 | F15: =E15+ SUMIF('InOut Inv'!F:H,$F$4&A15,'InOut Inv'!H:H) - SUMIF('Daily Sales'!F:I,$F$4&A15,'Daily Sales'!I:I) -> 3 | G15: =F15+ SUMIF('InOut Inv'!G:I,$F$4&B15,'InOut Inv'!I:I) - SUMIF('Daily Sales'!G:J,$F$4&B15,'Daily Sales'!J:J) -> 3
A16: MT1012 | B16: MEDIA TANAM | C16: MEDIA TANAM | D16: =VLOOKUP(A16,Master!D:G,4,0) -> #N/A | E16: 8 | F16: =E16+ SUMIF('InOut Inv'!F:H,$F$4&A16,'InOut Inv'!H:H) - SUMIF('Daily Sales'!F:I,$F$4&A16,'Daily Sales'!I:I) -> 8 | G16: =F16+ SUMIF('InOut Inv'!G:I,$F$4&B16,'InOut Inv'!I:I) - SUMIF('Daily Sales'!G:J,$F$4&B16,'Daily Sales'!J:J) -> 8
A17: MT1013 | B17: MEDIA TANAM | C17: MEDIA TANAM | D17: =VLOOKUP(A17,Master!D:G,4,0) -> #N/A | E17: 2 | F17: =E17+ SUMIF('InOut Inv'!F:H,$F$4&A17,'InOut Inv'!H:H) - SUMIF('Daily Sales'!F:I,$F$4&A17,'Daily Sales'!I:I) -> 2 | G17: =F17+ SUMIF('InOut Inv'!G:I,$F$4&B17,'InOut Inv'!I:I) - SUMIF('Daily Sales'!G:J,$F$4&B17,'Daily Sales'!J:J) -> 2
A18: MT1014 | B18: MEDIA TANAM | C18: MEDIA TANAM | D18: =VLOOKUP(A18,Master!D:G,4,0) -> #N/A | E18: 2 | F18: =E18+ SUMIF('InOut Inv'!F:H,$F$4&A18,'InOut Inv'!H:H) - SUMIF('Daily Sales'!F:I,$F$4&A18,'Daily Sales'!I:I) -> 2 | G18: =F18+ SUMIF('InOut Inv'!G:I,$F$4&B18,'InOut Inv'!I:I) - SUMIF('Daily Sales'!G:J,$F$4&B18,'Daily Sales'!J:J) -> 2
A19: MT1015 | B19: MEDIA TANAM | C19: MEDIA TANAM | D19: =VLOOKUP(A19,Master!D:G,4,0) -> #N/A | E19: 17 | F19: =E19+ SUMIF('InOut Inv'!F:H,$F$4&A19,'InOut Inv'!H:H) - SUMIF('Daily Sales'!F:I,$F$4&A19,'Daily Sales'!I:I) -> 17 | G19: =F19+ SUMIF('InOut Inv'!G:I,$F$4&B19,'InOut Inv'!I:I) - SUMIF('Daily Sales'!G:J,$F$4&B19,'Daily Sales'!J:J) -> 17
A20: MT1016 | B20: MEDIA TANAM | C20: MEDIA TANAM | D20: =VLOOKUP(A20,Master!D:G,4,0) -> #N/A | E20: 9 | F20: =E20+ SUMIF('InOut Inv'!F:H,$F$4&A20,'InOut Inv'!H:H) - SUMIF('Daily Sales'!F:I,$F$4&A20,'Daily Sales'!I:I) -> 9 | G20: =F20+ SUMIF('InOut Inv'!G:I,$F$4&B20,'InOut Inv'!I:I) - SUMIF('Daily Sales'!G:J,$F$4&B20,'Daily Sales'!J:J) -> 9
A21: MT1017 | B21: MEDIA TANAM | C21: MEDIA TANAM | D21: =VLOOKUP(A21,Master!D:G,4,0) -> #N/A | E21: 0 | F21: =E21+ SUMIF('InOut Inv'!F:H,$F$4&A21,'InOut Inv'!H:H) - SUMIF('Daily Sales'!F:I,$F$4&A21,'Daily Sales'!I:I) -> 0 | G21: =F21+ SUMIF('InOut Inv'!G:I,$F$4&B21,'InOut Inv'!I:I) - SUMIF('Daily Sales'!G:J,$F$4&B21,'Daily Sales'!J:J) -> 0
A22: MT1018 | B22: MEDIA TANAM | C22: MEDIA TANAM | D22: =VLOOKUP(A22,Master!D:G,4,0) -> #N/A | E22: 0 | F22: =E22+ SUMIF('InOut Inv'!F:H,$F$4&A22,'InOut Inv'!H:H) - SUMIF('Daily Sales'!F:I,$F$4&A22,'Daily Sales'!I:I) -> 0 | G22: =F22+ SUMIF('InOut Inv'!G:I,$F$4&B22,'InOut Inv'!I:I) - SUMIF('Daily Sales'!G:J,$F$4&B22,'Daily Sales'!J:J) -> 0
A23: MT1019 | B23: MEDIA TANAM | C23: MEDIA TANAM | D23: =VLOOKUP(A23,Master!D:G,4,0) -> #N/A | E23: 4 | F23: =E23+ SUMIF('InOut Inv'!F:H,$F$4&A23,'InOut Inv'!H:H) - SUMIF('Daily Sales'!F:I,$F$4&A23,'Daily Sales'!I:I) -> 4 | G23: =F23+ SUMIF('InOut Inv'!G:I,$F$4&B23,'InOut Inv'!I:I) - SUMIF('Daily Sales'!G:J,$F$4&B23,'Daily Sales'!J:J) -> 4
A24: MT1020 | B24: MEDIA TANAM | C24: MEDIA TANAM | D24: =VLOOKUP(A24,Master!D:G,4,0) -> #N/A | E24: 0 | F24: =E24+ SUMIF('InOut Inv'!F:H,$F$4&A24,'InOut Inv'!H:H) - SUMIF('Daily Sales'!F:I,$F$4&A24,'Daily Sales'!I:I) -> 0 | G24: =F24+ SUMIF('InOut Inv'!G:I,$F$4&B24,'InOut Inv'!I:I) - SUMIF('Daily Sales'!G:J,$F$4&B24,'Daily Sales'!J:J) -> 0
A25: MT1021 | B25: MEDIA TANAM | C25: MEDIA TANAM | D25: =VLOOKUP(A25,Master!D:G,4,0) -> #N/A | E25: 3 | F25: =E25+ SUMIF('InOut Inv'!F:H,$F$4&A25,'InOut Inv'!H:H) - SUMIF('Daily Sales'!F:I,$F$4&A25,'Daily Sales'!I:I) -> 3 | G25: =F25+ SUMIF('InOut Inv'!G:I,$F$4&B25,'InOut Inv'!I:I) - SUMIF('Daily Sales'!G:J,$F$4&B25,'Daily Sales'!J:J) -> 3
... A39: MT1035 | B39: MEDIA TANAM | C39: MEDIA TANAM | D39: =VLOOKUP(A39,Master!D:G,4,0) -> #N/A | E39: 6 | F39: =E39+ SUMIF('InOut Inv'!F:H,$F$4&A39,'InOut Inv'!H:H) - SUMIF('Daily Sales'!F:I,$F$4&A39,'Daily Sales'!I:I) -> 6 | G39: =F39+ SUMIF('InOut Inv'!G:I,$F$4&B39,'InOut Inv'!I:I) - SUMIF('Daily Sales'!G:J,$F$4&B39,'Daily Sales'!J:J) -> 6
A40: MT1036 | B40: MEDIA TANAM | C40: MEDIA TANAM | D40: =VLOOKUP(A40,Master!D:G,4,0) -> #N/A | F40: =E40+ SUMIF('InOut Inv'!F:H,$F$4&A40,'InOut Inv'!H:H) - SUMIF('Daily Sales'!F:I,$F$4&A40,'Daily Sales'!I:I) -> 0 | G40: =F40+ SUMIF('InOut Inv'!G:I,$F$4&B40,'InOut Inv'!I:I) - SUMIF('Daily Sales'!G:J,$F$4&B40,'Daily Sales'!J:J) -> 0
A41: MT1037 | B41: MEDIA TANAM | C41: MEDIA TANAM | D41: =VLOOKUP(A41,Master!D:G,4,0) -> #N/A | F41: =E41+ SUMIF('InOut Inv'!F:H,$F$4&A41,'InOut Inv'!H:H) - SUMIF('Daily Sales'!F:I,$F$4&A41,'Daily Sales'!I:I) -> 0 | G41: =F41+ SUMIF('InOut Inv'!G:I,$F$4&B41,'InOut Inv'!I:I) - SUMIF('Daily Sales'!G:J,$F$4&B41,'Daily Sales'!J:J) -> 0
A42: MT1038 | B42: MEDIA TANAM | C42: MEDIA TANAM | D42: =VLOOKUP(A42,Master!D:G,4,0) -> #N/A | E42: 3 | F42: =E42+ SUMIF('InOut Inv'!F:H,$F$4&A42,'InOut Inv'!H:H) - SUMIF('Daily Sales'!F:I,$F$4&A42,'Daily Sales'!I:I) -> 3 | G42: =F42+ SUMIF('InOut Inv'!G:I,$F$4&B42,'InOut Inv'!I:I) - SUMIF('Daily Sales'!G:J,$F$4&B42,'Daily Sales'!J:J) -> 3
A43: PL1001 | B43: PERLENGKAPAN | C43: CATOK | D43: =VLOOKUP(A43,Master!D:G,4,0) -> #N/A | E43: 1 | F43: =E43+ SUMIF('InOut Inv'!F:H,$F$4&A43,'InOut Inv'!H:H) - SUMIF('Daily Sales'!F:I,$F$4&A43,'Daily Sales'!I:I) -> 1 | G43: =F43+ SUMIF('InOut Inv'!G:I,$F$4&B43,'InOut Inv'!I:I) - SUMIF('Daily Sales'!G:J,$F$4&B43,'Daily Sales'!J:J) -> 1
A44: PL1002 | B44: PERLENGKAPAN | C44: CATOK | D44: =VLOOKUP(A44,Master!D:G,4,0) -> #N/A | E44: 2 | F44: =E44+ SUMIF('InOut Inv'!F:H,$F$4&A44,'InOut Inv'!H:H) - SUMIF('Daily Sales'!F:I,$F$4&A44,'Daily Sales'!I:I) -> 2 | G44: =F44+ SUMIF('InOut Inv'!G:I,$F$4&B44,'InOut Inv'!I:I) - SUMIF('Daily Sales'!G:J,$F$4&B44,'Daily Sales'!J:J) -> 2
A45: PL2001 | B45: PERLENGKAPAN | C45: GUNTING | D45: =VLOOKUP(A45,Master!D:G,4,0) -> #N/A | E45: 2 | F45: =E45+ SUMIF('InOut Inv'!F:H,$F$4&A45,'InOut Inv'!H:H) - SUMIF('Daily Sales'!F:I,$F$4&A45,'Daily Sales'!I:I) -> 2 | G45: =F45+ SUMIF('InOut Inv'!G:I,$F$4&B45,'InOut Inv'!I:I) - SUMIF('Daily Sales'!G:J,$F$4&B45,'Daily Sales'!J:J) -> 2
A46: PL2002 | B46: PERLENGKAPAN | C46: GUNTING | D46: =VLOOKUP(A46,Master!D:G,4,0) -> #N/A | E46: 1 | F46: =E46+ SUMIF('InOut Inv'!F:H,$F$4&A46,'InOut Inv'!H:H) - SUMIF('Daily Sales'!F:I,$F$4&A46,'Daily Sales'!I:I) -> 1 | G46: =F46+ SUMIF('InOut Inv'!G:I,$F$4&B46,'InOut Inv'!I:I) - SUMIF('Daily Sales'!G:J,$F$4&B46,'Daily Sales'!J:J) -> 1
A47: PL2003 | B47: PERLENGKAPAN | C47: GUNTING | D47: =VLOOKUP(A47,Master!D:G,4,0) -> #N/A | E47: 2 | F47: =E47+ SUMIF('InOut Inv'!F:H,$F$4&A47,'InOut Inv'!H:H) - SUMIF('Daily Sales'!F:I,$F$4&A47,'Daily Sales'!I:I) -> 2 | G47: =F47+ SUMIF('InOut Inv'!G:I,$F$4&B47,'InOut Inv'!I:I) - SUMIF('Daily Sales'!G:J,$F$4&B47,'Daily Sales'!J:J) -> 2
A48: PL2004 | B48: PERLENGKAPAN | C48: GUNTING | D48: =VLOOKUP(A48,Master!D:G,4,0) -> #N/A | E48: 3 | F48: =E48+ SUMIF('InOut Inv'!F:H,$F$4&A48,'InOut Inv'!H:H) - SUMIF('Daily Sales'!F:I,$F$4&A48,'Daily Sales'!I:I) -> 3 | G48: =F48+ SUMIF('InOut Inv'!G:I,$F$4&B48,'InOut Inv'!I:I) - SUMIF('Daily Sales'!G:J,$F$4&B48,'Daily Sales'!J:J) -> 3
A49: PL2005 | B49: PERLENGKAPAN | C49: GUNTING | D49: =VLOOKUP(A49,Master!D:G,4,0) -> #N/A | E49: 2 | F49: =E49+ SUMIF('InOut Inv'!F:H,$F$4&A49,'InOut Inv'!H:H) - SUMIF('Daily Sales'!F:I,$F$4&A49,'Daily Sales'!I:I) -> 2 | G49: =F49+ SUMIF('InOut Inv'!G:I,$F$4&B49,'InOut Inv'!I:I) - SUMIF('Daily Sales'!G:J,$F$4&B49,'Daily Sales'!J:J) -> 2
A50: PL2006 | B50: PERLENGKAPAN | C50: GUNTING | D50: =VLOOKUP(A50,Master!D:G,4,0) -> #N/A | E50: 3 | F50: =E50+ SUMIF('InOut Inv'!F:H,$F$4&A50,'InOut Inv'!H:H) - SUMIF('Daily Sales'!F:I,$F$4&A50,'Daily Sales'!I:I) -> 3 | G50: =F50+ SUMIF('InOut Inv'!G:I,$F$4&B50,'InOut Inv'!I:I) - SUMIF('Daily Sales'!G:J,$F$4&B50,'Daily Sales'!J:J) -> 3
A51: PL2007 | B51: PERLENGKAPAN | C51: GUNTING | D51: =VLOOKUP(A51,Master!D:G,4,0) -> #N/A | E51: 4 | F51: =E51+ SUMIF('InOut Inv'!F:H,$F$4&A51,'InOut Inv'!H:H) - SUMIF('Daily Sales'!F:I,$F$4&A51,'Daily Sales'!I:I) -> 4 | G51: =F51+ SUMIF('InOut Inv'!G:I,$F$4&B51,'InOut Inv'!I:I) - SUMIF('Daily Sales'!G:J,$F$4&B51,'Daily Sales'!J:J) -> 4
A52: PL2008 | B52: PERLENGKAPAN | C52: GUNTING | D52: =VLOOKUP(A52,Master!D:G,4,0) -> #N/A | E52: 1 | F52: =E52+ SUMIF('InOut Inv'!F:H,$F$4&A52,'InOut Inv'!H:H) - SUMIF('Daily Sales'!F:I,$F$4&A52,'Daily Sales'!I:I) -> 1 | G52: =F52+ SUMIF('InOut Inv'!G:I,$F$4&B52,'InOut Inv'!I:I) - SUMIF('Daily Sales'!G:J,$F$4&B52,'Daily Sales'!J:J) -> 1
A53: PL2009 | B53: PERLENGKAPAN | C53: GUNTING | D53: =VLOOKUP(A53,Master!D:G,4,0) -> #N/A | E53: 3 | F53: =E53+ SUMIF('InOut Inv'!F:H,$F$4&A53,'InOut Inv'!H:H) - SUMIF('Daily Sales'!F:I,$F$4&A53,'Daily Sales'!I:I) -> 3 | G53: =F53+ SUMIF('InOut Inv'!G:I,$F$4&B53,'InOut Inv'!I:I) - SUMIF('Daily Sales'!G:J,$F$4&B53,'Daily Sales'!J:J) -> 3
... A98: PL4006 | B98: PERLENGKAPAN | C98: PERLENGKAPAN LAIN | D98: =VLOOKUP(A98,Master!D:G,4,0) -> #N/A | E98: 2 | F98: =E98+ SUMIF('InOut Inv'!F:H,$F$4&A98,'InOut Inv'!H:H) - SUMIF('Daily Sales'!F:I,$F$4&A98,'Daily Sales'!I:I) -> 2 | G98: =F98+ SUMIF('InOut Inv'!G:I,$F$4&B98,'InOut Inv'!I:I) - SUMIF('Daily Sales'!G:J,$F$4&B98,'Daily Sales'!J:J) -> 2
A99: PL4007 | B99: PERLENGKAPAN | C99: PERLENGKAPAN LAIN | D99: =VLOOKUP(A99,Master!D:G,4,0) -> #N/A | F99: =E99+ SUMIF('InOut Inv'!F:H,$F$4&A99,'InOut Inv'!H:H) - SUMIF('Daily Sales'!F:I,$F$4&A99,'Daily Sales'!I:I) -> 0 | G99: =F99+ SUMIF('InOut Inv'!G:I,$F$4&B99,'InOut Inv'!I:I) - SUMIF('Daily Sales'!G:J,$F$4&B99,'Daily Sales'!J:J) -> 0
A100: PL4008 | B100: PERLENGKAPAN | C100: PERLENGKAPAN LAIN | D100: =VLOOKUP(A100,Master!D:G,4,0) -> #N/A | E100: 0 | F100: =E100+ SUMIF('InOut Inv'!F:H,$F$4&A100,'InOut Inv'!H:H) - SUMIF('Daily Sales'!F:I,$F$4&A100,'Daily Sales'!I:I) -> 0 | G100: =F100+ SUMIF('InOut Inv'!G:I,$F$4&B100,'InOut Inv'!I:I) - SUMIF('Daily Sales'!G:J,$F$4&B100,'Daily Sales'!J:J) -> 0
...

Sheet InOut Inv
A2: INVENTORY IN - OUT OCTOBER 2024
A4: Date | B4: Time | C4: INV. NO | D4: Vendor | E4: Code | F4: z | G4: Item Descriptions | H4: Qty | I4: Price | J4: Discount | K4: Total | L4: Payment | M4: Type
A5: 01/10/24 | B5: 09:00:00 | F5: =A5&E5 -> 01/10/24 | G5: =_xludf.IFNA(VLOOKUP(E5,Master!D:J,4,0),"") -> #NAME? | I5: 0 | J5: 0 | K5: =I5*H5-J5 -> 0 | L5: C | M5: INCOMING
A6: 03/10/24 | B6: 08:45:00 | C6: 14107 | D6: TRIA GARDEN | E6: PK1045 | F6: =A6&E6 -> 03/10/24PK1045 | G6: =_xludf.IFNA(VLOOKUP(E6,Master!D:J,4,0),"") -> #NAME? | H6: 1 | I6: 30000 | J6: 0 | K6: =I6*H6-J6 -> 30000 | L6: C | M6: INCOMING
A7: 03/10/24 | B7: 08:45:00 | C7: 14574 | D7: TRIA GARDEN | E7: PK1011 | F7: =A7&E7 -> 03/10/24PK1011 | G7: =_xludf.IFNA(VLOOKUP(E7,Master!D:J,4,0),"") -> #NAME? | H7: 3 | I7: 74000 | J7: 0 | K7: =I7*H7-J7 -> 222000 | L7: C | M7: INCOMING
A8: 04/10/24 | B8: 08:29:00 | C8: 14687 | D8: TRIA GARDEN | E8: PS3009 | F8: =A8&E8 -> 04/10/24PS3009 | G8: =_xludf.IFNA(VLOOKUP(E8,Master!D:J,4,0),"") -> #NAME? | H8: 1 | I8: 68000 | J8: 0 | K8: =I8*H8-J8 -> 68000 | L8: C | M8: INCOMING
A9: 04/10/24 | B9: 08:29:00 | C9: 14687 | D9: TRIA GARDEN | E9: PL3015 | F9: =A9&E9 -> 04/10/24PL3015 | G9: =_xludf.IFNA(VLOOKUP(E9,Master!D:J,4,0),"") -> #NAME? | H9: 1 | I9: 85000 | J9: 0 | K9: =I9*H9-J9 -> 85000 | L9: C | M9: INCOMING
A10: 04/10/24 | B10: 08:29:00 | C10: 14687 | D10: TRIA GARDEN | E10: PL3017 | F10: =A10&E10 -> 04/10/24PL3017 | G10: =_xludf.IFNA(VLOOKUP(E10,Master!D:J,4,0),"") -> #NAME? | H10: 1 | I10: 85000 | J10: 0 | K10: =I10*H10-J10 -> 85000 | L10: C | M10: INCOMING
A11: 04/10/24 | B11: 08:29:00 | C11: 14687 | D11: TRIA GARDEN | E11: PL3021 | F11: =A11&E11 -> 04/10/24PL3021 | G11: =_xludf.IFNA(VLOOKUP(E11,Master!D:J,4,0),"") -> #NAME? | H11: 1 | I11: 85000 | J11: 0 | K11: =I11*H11-J11 -> 85000 | L11: C | M11: INCOMING
A12: 04/10/24 | B12: 08:29:00 | C12: 14687 | D12: TRIA GARDEN | E12: PL3023 | F12: =A12&E12 -> 04/10/24PL3023 | G12: =_xludf.IFNA(VLOOKUP(E12,Master!D:J,4,0),"") -> #NAME? | H12: 2 | I12: 85000 | J12: 0 | K12: =I12*H12-J12 -> 170000 | L12: C | M12: INCOMING
A13: 04/10/24 | B13: 08:29:00 | C13: 14687 | D13: TRIA GARDEN | E13: PS3011 | F13: =A13&E13 -> 04/10/24PS3011 | G13: =_xludf.IFNA(VLOOKUP(E13,Master!D:J,4,0),"") -> #NAME? | H13: 1 | I13: 105000 | J13: 0 | K13: =I13*H13-J13 -> 105000 | L13: C | M13: INCOMING
A14: 04/10/24 | B14: 08:29:00 | C14: 17193 | D14: TRIA GARDEN | E14: PL4022 | F14: =A14&E14 -> 04/10/24PL4022 | G14: =_xludf.IFNA(VLOOKUP(E14,Master!D:J,4,0),"") -> #NAME? | H14: 2 | I14: 29000 | J14: 0 | K14: =I14*H14-J14 -> 58000 | L14: C | M14: INCOMING
A15: 04/10/24 | B15: 08:29:00 | C15: 17193 | D15: TRIA GARDEN | E15: PL4023 | F15: =A15&E15 -> 04/10/24PL4023 | G15: =_xludf.IFNA(VLOOKUP(E15,Master!D:J,4,0),"") -> #NAME? | H15: 2 | I15: 33000 | J15: 0 | K15: =I15*H15-J15 -> 66000 | L15: C | M15: INCOMING
A16: 04/10/24 | B16: 08:29:00 | C16: 17193 | D16: TRIA GARDEN | E16: PK1028 | F16: =A16&E16 -> 04/10/24PK1028 | G16: =_xludf.IFNA(VLOOKUP(E16,Master!D:J,4,0),"") -> #NAME? | H16: 7 | I16: 19000 | J16: 0 | K16: =I16*H16-J16 -> 133000 | L16: C | M16: INCOMING
A17: 04/10/24 | B17: 08:29:00 | C17: 17193 | D17: TRIA GARDEN | E17: PK1014 | F17: =A17&E17 -> 04/10/24PK1014 | G17: =_xludf.IFNA(VLOOKUP(E17,Master!D:J,4,0),"") -> #NAME? | H17: 3 | I17: 12000 | J17: 0 | K17: =I17*H17-J17 -> 36000 | L17: C | M17: INCOMING
... A19: 04/10/24 | B19: 08:29:00 | C19: 17193 | D19: TRIA GARDEN | E19: PK1013 | F19: =A19&E19 -> 04/10/24PK1013 | G19: =_xludf.IFNA(VLOOKUP(E19,Master!D:J,4,0),"") -> #NAME? | H19: 1 | I19: 24000 | J19: 0 | K19: =I19*H19-J19 -> 24000 | L19: C | M19: INCOMING
A20: 04/10/24 | B20: 08:29:00 | C20: 17193 | D20: TRIA GARDEN | E20: PL6010 | F20: =A20&E20 -> 04/10/24PL6010 | G20: =_xludf.IFNA(VLOOKUP(E20,Master!D:J,4,0),"") -> #NAME? | H20: 24 | I20: =27000/12 -> 2250 | J20: 0 | K20: =I20*H20-J20 -> 54000 | L20: C | M20: INCOMING
A21: 04/10/24 | B21: 08:29:00 | C21: 17193 | D21: TRIA GARDEN | E21: PK1038 | F21: =A21&E21 -> 04/10/24PK1038 | G21: =_xludf.IFNA(VLOOKUP(E21,Master!D:J,4,0),"") -> #NAME? | H21: 4 | I21: 6000 | J21: 0 | K21: =I21*H21-J21 -> 24000 | L21: C | M21: INCOMING
A22: 04/10/24 | B22: 08:29:00 | C22: 17193 | D22: TRIA GARDEN | E22: MT1004 | F22: =A22&E22 -> 04/10/24MT1004 | G22: =_xludf.IFNA(VLOOKUP(E22,Master!D:J,4,0),"") -> #NAME? | H22: 5 | I22: 18000 | J22: 0 | K22: =I22*H22-J22 -> 90000 | L22: C | M22: INCOMING
A23: 07/10/24 | B23: 08:34:00 | C23: 14734 | D23: TRIA GARDEN | E23: PS3010 | F23: =A23&E23 -> 07/10/24PS3010 | G23: =_xludf.IFNA(VLOOKUP(E23,Master!D:J,4,0),"") -> #NAME? | H23: 1 | I23: 20000 | J23: 0 | K23: =I23*H23-J23 -> 20000 | L23: C | M23: INCOMING
A24: 07/10/24 | B24: 08:34:00 | C24: 14734 | D24: TRIA GARDEN | E24: PK1023 | F24: =A24&E24 -> 07/10/24PK1023 | G24: =_xludf.IFNA(VLOOKUP(E24,Master!D:J,4,0),"") -> #NAME? | H24: 2 | I24: 25000 | J24: 0 | K24: =I24*H24-J24 -> 50000 | L24: C | M24: INCOMING
A25: 07/10/24 | B25: 08:37:00 | C25: 17433 | D25: TRIA GARDEN | E25: MT1014 | F25: =A25&E25 -> 07/10/24MT1014 | G25: =_xludf.IFNA(VLOOKUP(E25,Master!D:J,4,0),"") -> #NAME? | H25: 10 | I25: 4000 | J25: 0 | K25: =I25*H25-J25 -> 40000 | L25: C | M25: INCOMING
A26: 07/10/24 | B26: 08:34:00 | C26: 17431 | D26: TRIA GARDEN | E26: PK1012 | F26: =A26&E26 -> 07/10/24PK1012 | G26: =_xludf.IFNA(VLOOKUP(E26,Master!D:J,4,0),"") -> #NAME? | H26: 3 | I26: 25000 | J26: 0 | K26: =I26*H26-J26 -> 75000 | L26: C | M26: INCOMING
A27: 07/10/24 | B27: 08:34:00 | C27: 17431 | D27: TRIA GARDEN | E27: PK1051 | F27: =A27&E27 -> 07/10/24PK1051 | G27: =_xludf.IFNA(VLOOKUP(E27,Master!D:J,4,0),"") -> #NAME? | H27: 1 | I27: 45000 | J27: 0 | K27: =I27*H27-J27 -> 45000 | L27: C | M27: INCOMING
A28: 07/10/24 | B28: 08:34:00 | C28: 17431 | D28: TRIA GARDEN | E28: PK1052 | F28: =A28&E28 -> 07/10/24PK1052 | G28: =_xludf.IFNA(VLOOKUP(E28,Master!D:J,4,0),"") -> #NAME? | H28: 1 | I28: 60000 | J28: 0 | K28: =I28*H28-J28 -> 60000 | L28: C | M28: INCOMING
A29: 07/10/24 | B29: 08:34:00 | C29: 17431 | D29: TRIA GARDEN | E29: PK1038 | F29: =A29&E29 -> 07/10/24PK1038 | G29: =_xludf.IFNA(VLOOKUP(E29,Master!D:J,4,0),"") -> #NAME? | H29: 2 | I29: 6000 | J29: 0 | K29: =I29*H29-J29 -> 12000 | L29: C | M29: INCOMING
A30: 07/10/24 | B30: 08:34:00 | C30: 17431 | D30: TRIA GARDEN | E30: PL4023 | F30: =A30&E30 -> 07/10/24PL4023 | G30: =_xludf.IFNA(VLOOKUP(E30,Master!D:J,4,0),"") -> #NAME? | H30: 1 | I30: 33000 | J30: 0 | K30: =I30*H30-J30 -> 33000 | L30: C | M30: INCOMING
A31: 07/10/24 | B31: 08:34:00 | C31: 17431 | D31: TRIA GARDEN | E31: PL6028 | F31: =A31&E31 -> 07/10/24PL6028 | G31: =_xludf.IFNA(VLOOKUP(E31,Master!D:J,4,0),"") -> #NAME? | H31: 12 | I31: =30000/12 -> 2500 | J31: 0 | K31: =I31*H31-J31 -> 30000 | L31: C | M31: INCOMING
A32: 07/10/24 | B32: 08:34:00 | C32: 17431 | D32: TRIA GARDEN | E32: PL6029 | F32: =A32&E32 -> 07/10/24PL6029 | G32: =_xludf.IFNA(VLOOKUP(E32,Master!D:J,4,0),"") -> #NAME? | H32: 12 | I32: =42000/12 -> 3500 | J32: 0 | K32: =I32*H32-J32 -> 42000 | L32: C | M32: INCOMING
A33: 07/10/24 | B33: 08:34:00 | C33: 17431 | D33: TRIA GARDEN | E33: PL6011 | F33: =A33&E33 -> 07/10/24PL6011 | G33: =_xludf.IFNA(VLOOKUP(E33,Master!D:J,4,0),"") -> #NAME? | H33: 12 | I33: =45000/12 -> 3750 | J33: 0 | K33: =I33*H33-J33 -> 45000 | L33: C | M33: INCOMING
A34: 07/10/24 | F34: =A34&E34 -> 07/10/24 | G34: =_xludf.IFNA(VLOOKUP(E34,Master!D:J,4,0),"") -> #NAME? | H34: 0 | I34: 0 | J34: 0 | K34: =I34*H34-J34 -> 0 | L34: C | M34: INCOMING
A35: 07/10/24 | F35: =A35&E35 -> 07/10/24 | G35: =_xludf.IFNA(VLOOKUP(E35,Master!D:J,4,0),"") -> #NAME? | H35: 0 | I35: 0 | J35: 0 | K35: =I35*H35-J35 -> 0 | L35: C | M35: INCOMING
A36: 08/10/24 | B36: 08:35:00 | C36: 14757 | D36: TRIA GARDEN | E36: PS3012 | F36: =A36&E36 -> 08/10/24PS3012 | G36: =_xludf.IFNA(VLOOKUP(E36,Master!D:J,4,0),"") -> #NAME? | H36: 1 | I36: 40000 | J36: 0 | K36: =I36*H36-J36 -> 40000 | L36: C | M36: INCOMING
A37: 08/10/24 | B37: 08:35:00 | C37: 14757 | D37: TRIA GARDEN | E37: PS3009 | F37: =A37&E37 -> 08/10/24PS3009 | G37: =_xludf.IFNA(VLOOKUP(E37,Master!D:J,4,0),"") -> #NAME? | H37: 2 | I37: 68000 | J37: 0 | K37: =I37*H37-J37 -> 136000 | L37: C | M37: INCOMING
A38: 08/10/24 | B38: 08:35:00 | C38: 17518 | D38: TRIA GARDEN | E38: PK1014 | F38: =A38&E38 -> 08/10/24PK1014 | G38: =_xludf.IFNA(VLOOKUP(E38,Master!D:J,4,0),"") -> #NAME? | H38: 5 | I38: 12000 | J38: 0 | K38: =I38*H38-J38 -> 60000 | L38: C | M38: INCOMING
A39: 08/10/24 | B39: 08:35:00 | C39: 17518 | D39: TRIA GARDEN | E39: PS1001 | F39: =A39&E39 -> 08/10/24PS1001 | G39: =_xludf.IFNA(VLOOKUP(E39,Master!D:J,4,0),"") -> #NAME? | H39: 1 | I39: 43000 | J39: 0 | K39: =I39*H39-J39 -> 43000 | L39: C | M39: INCOMING
A40: 08/10/24 | B40: 08:35:00 | C40: 17518 | D40: TRIA GARDEN | E40: PK1011 | F40: =A40&E40 -> 08/10/24PK1011 | G40: =_xludf.IFNA(VLOOKUP(E40,Master!D:J,4,0),"") -> #NAME? | H40: 2 | I40: 78000 | J40: 0 | K40: =I40*H40-J40 -> 156000 | L40: C | M40: INCOMING
A41: 08/10/24 | B41: 08:35:00 | C41: 17518 | D41: TRIA GARDEN | E41: PL6007 | F41: =A41&E41 -> 08/10/24PL6007 | G41: =_xludf.IFNA(VLOOKUP(E41,Master!D:J,4,0),"") -> #NAME? | H41: 12 | I41: =96000/12 -> 8000 | J41: 0 | K41: =I41*H41-J41 -> 96000 | L41: C | M41: INCOMING
A42: 08/10/24 | B42: 08:35:00 | C42: 17518 | D42: TRIA GARDEN | E42: PL6022 | F42: =A42&E42 -> 08/10/24PL6022 | G42: =_xludf.IFNA(VLOOKUP(E42,Master!D:J,4,0),"") -> #NAME? | H42: 3 | I42: 30500 | J42: 0 | K42: =I42*H42-J42 -> 91500 | L42: C | M42: INCOMING
A43: 08/10/24 | B43: 08:35:00 | C43: 17518 | D43: TRIA GARDEN | E43: PL6031 | F43: =A43&E43 -> 08/10/24PL6031 | G43: =_xludf.IFNA(VLOOKUP(E43,Master!D:J,4,0),"") -> #NAME? | H43: 2 | I43: 58000 | J43: 0 | K43: =I43*H43-J43 -> 116000 | L43: C | M43: INCOMING
...

Sheet Incoming
A2: INVENTORY INC NOVEMBER 2025
A4: Date | B4: Time | C4: INV. NO | D4: Vendor | E4: Code | F4: z | G4: Item Descriptions | H4: Qty | I4: Price | J4: Discount | K4: Total | L4: Payment | M4: Notes
F5: =A5&E5 | G5: =_xludf.IFNA(VLOOKUP(E5,Master!D:J,4,0),"") -> #NAME? | I5: 0 | J5: 0 | K5: =I5*H5-J5 -> 0 | L5: C
A6: 31/10/25 | B6: 17:04:00 | C6: 005771/KSR/TGB/1025 | D6: TRIA GARDEN | H6: 1 | I6: 30000 | J6: 0 | K6: 340000 | L6: T | M6: Trf pakai uang BNI
